Workbook

Sheet 说明
A1: 自建 UDP：384 对 i5/i7（10 nt 内联索引，4 个 96 组块，每块 2 个 48 组）
A2: 生成方式：程序从头生成，不借用 Illumina 序列；与 Illumina UDP0001–0384 的 i5/i7 没有任何相同序列（含反向互补），最小汉明距离 1。
A3: 单条规则：GC 4–6/10；无同聚物 ≥3、无二核苷酸重复 ≥3 次、无 GGGG；前两位不同时为 G；不含 TruSeq/Nextera/P5/P7 接头的 6-mer；非回文（与自身反向互补的编辑距离 ≥4）。
A4: 集合规则：768 条序列（384 个 i5 + 384 个 i7）两两 Levenshtein 编辑距离 ≥4（实测最小 4）；与对方反向互补的编辑距离 ≥3（严格要求 ≥4 时只能凑出 464 条，不够 768，因此放宽到 3，其余不变）。
A5: 每个周期（第 1–10 位）：GC、A+C、A+T 占比 40–60%，且 A/C/G/T 各 ≥15%。检验范围：每个 48 组、每个 96 组块（i5、i7 各自）和全部 384 个，共 26 组，全部达标（见“每周期统计”，公式计算）。
A6: 配对：同一块里 i5 与 i7 按编号配对（DN001 的 i5 与 i7 在同一管）。配对只是占位，你们结合引物筛选后可以重新配对（i5 之间、i7 之间的约束不受配对影响）。
A7: 二聚体预筛列 H、E：该索引（作为 5′ 尾巴的 10 nt）与 33 条引物池 198 个展开序列（不带尾巴）在 58 °C 的最差异源二聚体 ΔG（H）和池中引物 3′ 端对它的最差 3′ 锚定 ΔG（E），只作排序参考；每个管（i5+i7 加到整池后）的完整二聚体评估在后台运行，结果会补充。
A8: 没有评估的：真实接头；实验验证（条形码紧邻引物会带来扩增偏好，建议做同样品多条形码的对照实验）。

Sheet 384对
A1: 配对 | B1: 96 块 | C1: 48 组 | D1: i5 序列 | E1: i7 序列 | F1: i5 GC | G1: i7 GC | H1: i5 预筛 H | I1: i5 预筛 E | J1: i7 预筛 H | K1: i7 预筛 E | M1: i5 第1位 | N1: i5 第2位 | O1: i5 第3位 | P1: i5 第4位 | Q1: i5 第5位 | R1: i5 第6位 | S1: i5 第7位 | T1: i5 第8位 | U1: i5 第9位 | V1: i5 第10位 | W1: i7 第1位 | X1: i7 第2位 | Y1: i7 第3位 | Z1: i7 第4位 | AA1: i7 第5位 | AB1: i7 第6位 | AC1: i7 第7位 | AD1: i7 第8位 | AE1: i7 第9位 | AF1: i7 第10位
A2: DN001 | B2: 1 | C2: 1 | D2: GATATAGACG | E2: GTGCAAGGCA | F2: =LEN(SUBSTITUTE(SUBSTITUTE(D2,"A",""),"T","")) | G2: =LEN(SUBSTITUTE(SUBSTITUTE(E2,"A",""),"T","")) | H2: -2.23 | I2: -1.4 | J2: -3.48 | K2: -2.08 | M2: =MID($D2,1,1) | N2: =MID($D2,2,1) | O2: =MID($D2,3,1) | P2: =MID($D2,4,1) | Q2: =MID($D2,5,1) | R2: =MID($D2,6,1) | S2: =MID($D2,7,1) | T2: =MID($D2,8,1) | U2: =MID($D2,9,1) | V2: =MID($D2,10,1) | W2: =MID($E2,1,1) | X2: =MID($E2,2,1) | Y2: =MID($E2,3,1) | Z2: =MID($E2,4,1) | AA2: =MID($E2,5,1) | AB2: =MID($E2,6,1) | AC2: =MID($E2,7,1) | AD2: =MID($E2,8,1) | AE2: =MID($E2,9,1) | AF2: =MID($E2,10,1)
A3: DN002 | B3: 1 | C3: 1 | D3: CGGAATGGCA | E3: GACATCACTT | F3: =LEN(SUBSTITUTE(SUBSTITUTE(D3,"A",""),"T","")) | G3: =LEN(SUBSTITUTE(SUBSTITUTE(E3,"A",""),"T","")) | H3: -3 | I3: -2.75 | J3: -2.49 | K3: -0.19 | M3: =MID($D3,1,1) | N3: =MID($D3,2,1) | O3: =MID($D3,3,1) | P3: =MID($D3,4,1) | Q3: =MID($D3,5,1) | R3: =MID($D3,6,1) | S3: =MID($D3,7,1) | T3: =MID($D3,8,1) | U3: =MID($D3,9,1) | V3: =MID($D3,10,1) | W3: =MID($E3,1,1) | X3: =MID($E3,2,1) | Y3: =MID($E3,3,1) | Z3: =MID($E3,4,1) | AA3: =MID($E3,5,1) | AB3: =MID($E3,6,1) | AC3: =MID($E3,7,1) | AD3: =MID($E3,8,1) | AE3: =MID($E3,9,1) | AF3: =MID($E3,10,1)
A4: DN003 | B4: 1 | C4: 1 | D4: CCTATTACCT | E4: CTCCTGAATA | F4: =LEN(SUBSTITUTE(SUBSTITUTE(D4,"A",""),"T","")) | G4: =LEN(SUBSTITUTE(SUBSTITUTE(E4,"A",""),"T","")) | H4: -1.89 | I4: 0 | J4: -2.89 | K4: -0.26 | M4: =MID($D4,1,1) | N4: =MID($D4,2,1) | O4: =MID($D4,3,1) | P4: =MID($D4,4,1) | Q4: =MID($D4,5,1) | R4: =MID($D4,6,1) | S4: =MID($D4,7,1) | T4: =MID($D4,8,1) | U4: =MID($D4,9,1) | V4: =MID($D4,10,1) | W4: =MID($E4,1,1) | X4: =MID($E4,2,1) | Y4: =MID($E4,3,1) | Z4: =MID($E4,4,1) | AA4: =MID($E4,5,1) | AB4: =MID($E4,6,1) | AC4: =MID($E4,7,1) | AD4: =MID($E4,8,1) | AE4: =MID($E4,9,1) | AF4: =MID($E4,10,1)
A5: DN004 | B5: 1 | C5: 1 | D5: GCACTCAGGA | E5: TGAGGAACGC | F5: =LEN(SUBSTITUTE(SUBSTITUTE(D5,"A",""),"T","")) | G5: =LEN(SUBSTITUTE(SUBSTITUTE(E5,"A",""),"T","")) | H5: -2.29 | I5: -1.32 | J5: -3.32 | K5: -1.89 | M5: =MID($D5,1,1) | N5: =MID($D5,2,1) | O5: =MID($D5,3,1) | P5: =MID($D5,4,1) | Q5: =MID($D5,5,1) | R5: =MID($D5,6,1) | S5: =MID($D5,7,1) | T5: =MID($D5,8,1) | U5: =MID($D5,9,1) | V5: =MID($D5,10,1) | W5: =MID($E5,1,1) | X5: =MID($E5,2,1) | Y5: =MID($E5,3,1) | Z5: =MID($E5,4,1) | AA5: =MID($E5,5,1) | AB5: =MID($E5,6,1) | AC5: =MID($E5,7,1) | AD5: =MID($E5,8,1) | AE5: =MID($E5,9,1) | AF5: =MID($E5,10,1)
A6: DN005 | B6: 1 | C6: 1 | D6: CGACAGGTTG | E6: GACAGAGATT | F6: =LEN(SUBSTITUTE(SUBSTITUTE(D6,"A",""),"T","")) | G6: =LEN(SUBSTITUTE(SUBSTITUTE(E6,"A",""),"T","")) | H6: -2.39 | I6: -1.59 | J6: -2.25 | K6: -1.06 | M6: =MID($D6,1,1) | N6: =MID($D6,2,1) | O6: =MID($D6,3,1) | P6: =MID($D6,4,1) | Q6: =MID($D6,5,1) | R6: =MID($D6,6,1) | S6: =MID($D6,7,1) | T6: =MID($D6,8,1) | U6: =MID($D6,9,1) | V6: =MID($D6,10,1) | W6: =MID($E6,1,1) | X6: =MID($E6,2,1) | Y6: =MID($E6,3,1) | Z6: =MID($E6,4,1) | AA6: =MID($E6,5,1) | AB6: =MID($E6,6,1) | AC6: =MID($E6,7,1) | AD6: =MID($E6,8,1) | AE6: =MID($E6,9,1) | AF6: =MID($E6,10,1)
A7: DN006 | B7: 1 | C7: 1 | D7: GCCTTGCCTT | E7: TACGATGCCT | F7: =LEN(SUBSTITUTE(SUBSTITUTE(D7,"A",""),"T","")) | G7: =LEN(SUBSTITUTE(SUBSTITUTE(E7,"A",""),"T","")) | H7: -3.17 | I7: -2.09 | J7: -4.54 | K7: -2.3 | M7: =MID($D7,1,1) | N7: =MID($D7,2,1) | O7: =MID($D7,3,1) | P7: =MID($D7,4,1) | Q7: =MID($D7,5,1) | R7: =MID($D7,6,1) | S7: =MID($D7,7,1) | T7: =MID($D7,8,1) | U7: =MID($D7,9,1) | V7: =MID($D7,10,1) | W7: =MID($E7,1,1) | X7: =MID($E7,2,1) | Y7: =MID($E7,3,1) | Z7: =MID($E7,4,1) | AA7: =MID($E7,5,1) | AB7: =MID($E7,6,1) | AC7: =MID($E7,7,1) | AD7: =MID($E7,8,1) | AE7: =MID($E7,9,1) | AF7: =MID($E7,10,1)
A8: DN007 | B8: 1 | C8: 1 | D8: GCACCAAGCT | E8: AATAACGCTC | F8: =LEN(SUBSTITUTE(SUBSTITUTE(D8,"A",""),"T","")) | G8: =LEN(SUBSTITUTE(SUBSTITUTE(E8,"A",""),"T","")) | H8: -1.83 | I8: -1.2 | J8: -3.66 | K8: -1 | M8: =MID($D8,1,1) | N8: =MID($D8,2,1) | O8: =MID($D8,3,1) | P8: =MID($D8,4,1) | Q8: =MID($D8,5,1) | R8: =MID($D8,6,1) | S8: =MID($D8,7,1) | T8: =MID($D8,8,1) | U8: =MID($D8,9,1) | V8: =MID($D8,10,1) | W8: =MID($E8,1,1) | X8: =MID($E8,2,1) | Y8: =MID($E8,3,1) | Z8: =MID($E8,4,1) | AA8: =MID($E8,5,1) | AB8: =MID($E8,6,1) | AC8: =MID($E8,7,1) | AD8: =MID($E8,8,1) | AE8: =MID($E8,9,1) | AF8: =MID($E8,10,1)
A9: DN008 | B9: 1 | C9: 1 | D9: GTGGCTGTAC | E9: GCATTCTCCG | F9: =LEN(SUBSTITUTE(SUBSTITUTE(D9,"A",""),"T","")) | G9: =LEN(SUBSTITUTE(SUBSTITUTE(E9,"A",""),"T","")) | H9: -3.21 | I9: -2.97 | J9: -2.94 | K9: -0.27 | M9: =MID($D9,1,1) | N9: =MID($D9,2,1) | O9: =MID($D9,3,1) | P9: =MID($D9,4,1) | Q9: =MID($D9,5,1) | R9: =MID($D9,6,1) | S9: =MID($D9,7,1) | T9: =MID($D9,8,1) | U9: =MID($D9,9,1) | V9: =MID($D9,10,1) | W9: =MID($E9,1,1) | X9: =MID($E9,2,1) | Y9: =MID($E9,3,1) | Z9: =MID($E9,4,1) | AA9: =MID($E9,5,1) | AB9: =MID($E9,6,1) | AC9: =MID($E9,7,1) | AD9: =MID($E9,8,1) | AE9: =MID($E9,9,1) | AF9: =MID($E9,10,1)
A10: DN009 | B10: 1 | C10: 1 | D10: AGCCTTCACC | E10: AGGCGCCATT | F10: =LEN(SUBSTITUTE(SUBSTITUTE(D10,"A",""),"T","")) | G10: =LEN(SUBSTITUTE(SUBSTITUTE(E10,"A",""),"T","")) | H10: -2.36 | I10: -1.93 | J10: -4.02 | K10: -1.49 | M10: =MID($D10,1,1) | N10: =MID($D10,2,1) | O10: =MID($D10,3,1) | P10: =MID($D10,4,1) | Q10: =MID($D10,5,1) | R10: =MID($D10,6,1) | S10: =MID($D10,7,1) | T10: =MID($D10,8,1) | U10: =MID($D10,9,1) | V10: =MID($D10,10,1) | W10: =MID($E10,1,1) | X10: =MID($E10,2,1) | Y10: =MID($E10,3,1) | Z10: =MID($E10,4,1) | AA10: =MID($E10,5,1) | AB10: =MID($E10,6,1) | AC10: =MID($E10,7,1) | AD10: =MID($E10,8,1) | AE10: =MID($E10,9,1) | AF10: =MID($E10,10,1)
A11: DN010 | B11: 1 | C11: 1 | D11: ACCTTCGCTG | E11: AACTTGAGCT | F11: =LEN(SUBSTITUTE(SUBSTITUTE(D11,"A",""),"T","")) | G11: =LEN(SUBSTITUTE(SUBSTITUTE(E11,"A",""),"T","")) | H11: -3.85 | I11: -0.72 | J11: -1.97 | K11: -1.77 | M11: =MID($D11,1,1) | N11: =MID($D11,2,1) | O11: =MID($D11,3,1) | P11: =MID($D11,4,1) | Q11: =MID($D11,5,1) | R11: =MID($D11,6,1) | S11: =MID($D11,7,1) | T11: =MID($D11,8,1) | U11: =MID($D11,9,1) | V11: =MID($D11,10,1) | W11: =MID($E11,1,1) | X11: =MID($E11,2,1) | Y11: =MID($E11,3,1) | Z11: =MID($E11,4,1) | AA11: =MID($E11,5,1) | AB11: =MID($E11,6,1) | AC11: =MID($E11,7,1) | AD11: =MID($E11,8,1) | AE11: =MID($E11,9,1) | AF11: =MID($E11,10,1)
A12: DN011 | B12: 1 | C12: 1 | D12: AGAGGAGCCT | E12: TGGATGTCCG | F12: =LEN(SUBSTITUTE(SUBSTITUTE(D12,"A",""),"T","")) | G12: =LEN(SUBSTITUTE(SUBSTITUTE(E12,"A",""),"T","")) | H12: -3.27 | I12: -2.36 | J12: -2.36 | K12: -1.61 | M12: =MID($D12,1,1) | N12: =MID($D12,2,1) | O12: =MID($D12,3,1) | P12: =MID($D12,4,1) | Q12: =MID($D12,5,1) | R12: =MID($D12,6,1) | S12: =MID($D12,7,1) | T12: =MID($D12,8,1) | U12: =MID($D12,9,1) | V12: =MID($D12,10,1) | W12: =MID($E12,1,1) | X12: =MID($E12,2,1) | Y12: =MID($E12,3,1) | Z12: =MID($E12,4,1) | AA12: =MID($E12,5,1) | AB12: =MID($E12,6,1) | AC12: =MID($E12,7,1) | AD12: =MID($E12,8,1) | AE12: =MID($E12,9,1) | AF12: =MID($E12,10,1)
A13: DN012 | B13: 1 | C13: 1 | D13: GCGAGGAACT | E13: CATAAGCCGC | F13: =LEN(SUBSTITUTE(SUBSTITUTE(D13,"A",""),"T","")) | G13: =LEN(SUBSTITUTE(SUBSTITUTE(E13,"A",""),"T","")) | H13: -3.16 | I13: -3.16 | J13: -2.65 | K13: -1.05 | M13: =MID($D13,1,1) | N13: =MID($D13,2,1) | O13: =MID($D13,3,1) | P13: =MID($D13,4,1) | Q13: =MID($D13,5,1) | R13: =MID($D13,6,1) | S13: =MID($D13,7,1) | T13: =MID($D13,8,1) | U13: =MID($D13,9,1) | V13: =MID($D13,10,1) | W13: =MID($E13,1,1) | X13: =MID($E13,2,1) | Y13: =MID($E13,3,1) | Z13: =MID($E13,4,1) | AA13: =MID($E13,5,1) | AB13: =MID($E13,6,1) | AC13: =MID($E13,7,1) | AD13: =MID($E13,8,1) | AE13: =MID($E13,9,1) | AF13: =MID($E13,10,1)
... A385: DN384 | B385: 4 | C385: 8 | D385: CGTAACGCCT | E385: AGGCTATCGG | F385: =LEN(SUBSTITUTE(SUBSTITUTE(D385,"A",""),"T","")) | G385: =LEN(SUBSTITUTE(SUBSTITUTE(E385,"A",""),"T","")) | H385: -3.74 | I385: -2.03 | J385: -2.43 | K385: -2.1 | M385: =MID($D385,1,1) | N385: =MID($D385,2,1) | O385: =MID($D385,3,1) | P385: =MID($D385,4,1) | Q385: =MID($D385,5,1) | R385: =MID($D385,6,1) | S385: =MID($D385,7,1) | T385: =MID($D385,8,1) | U385: =MID($D385,9,1) | V385: =MID($D385,10,1) | W385: =MID($E385,1,1) | X385: =MID($E385,2,1) | Y385: =MID($E385,3,1) | Z385: =MID($E385,4,1) | AA385: =MID($E385,5,1) | AB385: =MID($E385,6,1) | AC385: =MID($E385,7,1) | AD385: =MID($E385,8,1) | AE385: =MID($E385,9,1) | AF385: =MID($E385,10,1)

Sheet 每周期统计
A1: 范围 | B1: 序列 | C1: 周期 | D1: A | E1: C | F1: G | G1: T | H1: GC% | I1: A+C% | J1: A+T% | K1: 是否达标
A2: 48 组 1 | B2: i5 | C2: 1 | D2: =COUNTIF('384对'!$M$2:$M$49,"A") | E2: =COUNTIF('384对'!$M$2:$M$49,"C") | F2: =COUNTIF('384对'!$M$2:$M$49,"G") | G2: =COUNTIF('384对'!$M$2:$M$49,"T") | H2: =(E2+F2)/48 | I2: =(D2+E2)/48 | J2: =(D2+G2)/48 | K2: =IF(AND(H2>=0.4,H2<=0.6,I2>=0.4,I2<=0.6,J2>=0.4,J2<=0.6,MIN(D2:G2)>=7.2),"是","否")
A3: 48 组 1 | B3: i5 | C3: 2 | D3: =COUNTIF('384对'!$N$2:$N$49,"A") | E3: =COUNTIF('384对'!$N$2:$N$49,"C") | F3: =COUNTIF('384对'!$N$2:$N$49,"G") | G3: =COUNTIF('384对'!$N$2:$N$49,"T") | H3: =(E3+F3)/48 | I3: =(D3+E3)/48 | J3: =(D3+G3)/48 | K3: =IF(AND(H3>=0.4,H3<=0.6,I3>=0.4,I3<=0.6,J3>=0.4,J3<=0.6,MIN(D3:G3)>=7.2),"是","否")
A4: 48 组 1 | B4: i5 | C4: 3 | D4: =COUNTIF('384对'!$O$2:$O$49,"A") | E4: =COUNTIF('384对'!$O$2:$O$49,"C") | F4: =COUNTIF('384对'!$O$2:$O$49,"G") | G4: =COUNTIF('384对'!$O$2:$O$49,"T") | H4: =(E4+F4)/48 | I4: =(D4+E4)/48 | J4: =(D4+G4)/48 | K4: =IF(AND(H4>=0.4,H4<=0.6,I4>=0.4,I4<=0.6,J4>=0.4,J4<=0.6,MIN(D4:G4)>=7.2),"是","否")
A5: 48 组 1 | B5: i5 | C5: 4 | D5: =COUNTIF('384对'!$P$2:$P$49,"A") | E5: =COUNTIF('384对'!$P$2:$P$49,"C") | F5: =COUNTIF('384对'!$P$2:$P$49,"G") | G5: =COUNTIF('384对'!$P$2:$P$49,"T") | H5: =(E5+F5)/48 | I5: =(D5+E5)/48 | J5: =(D5+G5)/48 | K5: =IF(AND(H5>=0.4,H5<=0.6,I5>=0.4,I5<=0.6,J5>=0.4,J5<=0.6,MIN(D5:G5)>=7.2),"是","否")
A6: 48 组 1 | B6: i5 | C6: 5 | D6: =COUNTIF('384对'!$Q$2:$Q$49,"A") | E6: =COUNTIF('384对'!$Q$2:$Q$49,"C") | F6: =COUNTIF('384对'!$Q$2:$Q$49,"G") | G6: =COUNTIF('384对'!$Q$2:$Q$49,"T") | H6: =(E6+F6)/48 | I6: =(D6+E6)/48 | J6: =(D6+G6)/48 | K6: =IF(AND(H6>=0.4,H6<=0.6,I6>=0.4,I6<=0.6,J6>=0.4,J6<=0.6,MIN(D6:G6)>=7.2),"是","否")
A7: 48 组 1 | B7: i5 | C7: 6 | D7: =COUNTIF('384对'!$R$2:$R$49,"A") | E7: =COUNTIF('384对'!$R$2:$R$49,"C") | F7: =COUNTIF('384对'!$R$2:$R$49,"G") | G7: =COUNTIF('384对'!$R$2:$R$49,"T") | H7: =(E7+F7)/48 | I7: =(D7+E7)/48 | J7: =(D7+G7)/48 | K7: =IF(AND(H7>=0.4,H7<=0.6,I7>=0.4,I7<=0.6,J7>=0.4,J7<=0.6,MIN(D7:G7)>=7.2),"是","否")
A8: 48 组 1 | B8: i5 | C8: 7 | D8: =COUNTIF('384对'!$S$2:$S$49,"A") | E8: =COUNTIF('384对'!$S$2:$S$49,"C") | F8: =COUNTIF('384对'!$S$2:$S$49,"G") | G8: =COUNTIF('384对'!$S$2:$S$49,"T") | H8: =(E8+F8)/48 | I8: =(D8+E8)/48 | J8: =(D8+G8)/48 | K8: =IF(AND(H8>=0.4,H8<=0.6,I8>=0.4,I8<=0.6,J8>=0.4,J8<=0.6,MIN(D8:G8)>=7.2),"是","否")
A9: 48 组 1 | B9: i5 | C9: 8 | D9: =COUNTIF('384对'!$T$2:$T$49,"A") | E9: =COUNTIF('384对'!$T$2:$T$49,"C") | F9: =COUNTIF('384对'!$T$2:$T$49,"G") | G9: =COUNTIF('384对'!$T$2:$T$49,"T") | H9: =(E9+F9)/48 | I9: =(D9+E9)/48 | J9: =(D9+G9)/48 | K9: =IF(AND(H9>=0.4,H9<=0.6,I9>=0.4,I9<=0.6,J9>=0.4,J9<=0.6,MIN(D9:G9)>=7.2),"是","否")
A10: 48 组 1 | B10: i5 | C10: 9 | D10: =COUNTIF('384对'!$U$2:$U$49,"A") | E10: =COUNTIF('384对'!$U$2:$U$49,"C") | F10: =COUNTIF('384对'!$U$2:$U$49,"G") | G10: =COUNTIF('384对'!$U$2:$U$49,"T") | H10: =(E10+F10)/48 | I10: =(D10+E10)/48 | J10: =(D10+G10)/48 | K10: =IF(AND(H10>=0.4,H10<=0.6,I10>=0.4,I10<=0.6,J10>=0.4,J10<=0.6,MIN(D10:G10)>=7.2),"是","否")
A11: 48 组 1 | B11: i5 | C11: 10 | D11: =COUNTIF('384对'!$V$2:$V$49,"A") | E11: =COUNTIF('384对'!$V$2:$V$49,"C") | F11: =COUNTIF('384对'!$V$2:$V$49,"G") | G11: =COUNTIF('384对'!$V$2:$V$49,"T") | H11: =(E11+F11)/48 | I11: =(D11+E11)/48 | J11: =(D11+G11)/48 | K11: =IF(AND(H11>=0.4,H11<=0.6,I11>=0.4,I11<=0.6,J11>=0.4,J11<=0.6,MIN(D11:G11)>=7.2),"是","否")
A12: 48 组 1 | B12: i7 | C12: 1 | D12: =COUNTIF('384对'!$W$2:$W$49,"A") | E12: =COUNTIF('384对'!$W$2:$W$49,"C") | F12: =COUNTIF('384对'!$W$2:$W$49,"G") | G12: =COUNTIF('384对'!$W$2:$W$49,"T") | H12: =(E12+F12)/48 | I12: =(D12+E12)/48 | J12: =(D12+G12)/48 | K12: =IF(AND(H12>=0.4,H12<=0.6,I12>=0.4,I12<=0.6,J12>=0.4,J12<=0.6,MIN(D12:G12)>=7.2),"是","否")
A13: 48 组 1 | B13: i7 | C13: 2 | D13: =COUNTIF('384对'!$X$2:$X$49,"A") | E13: =COUNTIF('384对'!$X$2:$X$49,"C") | F13: =COUNTIF('384对'!$X$2:$X$49,"G") | G13: =COUNTIF('384对'!$X$2:$X$49,"T") | H13: =(E13+F13)/48 | I13: =(D13+E13)/48 | J13: =(D13+G13)/48 | K13: =IF(AND(H13>=0.4,H13<=0.6,I13>=0.4,I13<=0.6,J13>=0.4,J13<=0.6,MIN(D13:G13)>=7.2),"是","否")
A14: 48 组 1 | B14: i7 | C14: 3 | D14: =COUNTIF('384对'!$Y$2:$Y$49,"A") | E14: =COUNTIF('384对'!$Y$2:$Y$49,"C") | F14: =COUNTIF('384对'!$Y$2:$Y$49,"G") | G14: =COUNTIF('384对'!$Y$2:$Y$49,"T") | H14: =(E14+F14)/48 | I14: =(D14+E14)/48 | J14: =(D14+G14)/48 | K14: =IF(AND(H14>=0.4,H14<=0.6,I14>=0.4,I14<=0.6,J14>=0.4,J14<=0.6,MIN(D14:G14)>=7.2),"是","否")
A15: 48 组 1 | B15: i7 | C15: 4 | D15: =COUNTIF('384对'!$Z$2:$Z$49,"A") | E15: =COUNTIF('384对'!$Z$2:$Z$49,"C") | F15: =COUNTIF('384对'!$Z$2:$Z$49,"G") | G15: =COUNTIF('384对'!$Z$2:$Z$49,"T") | H15: =(E15+F15)/48 | I15: =(D15+E15)/48 | J15: =(D15+G15)/48 | K15: =IF(AND(H15>=0.4,H15<=0.6,I15>=0.4,I15<=0.6,J15>=0.4,J15<=0.6,MIN(D15:G15)>=7.2),"是","否")
A16: 48 组 1 | B16: i7 | C16: 5 | D16: =COUNTIF('384对'!$AA$2:$AA$49,"A") | E16: =COUNTIF('384对'!$AA$2:$AA$49,"C") | F16: =COUNTIF('384对'!$AA$2:$AA$49,"G") | G16: =COUNTIF('384对'!$AA$2:$AA$49,"T") | H16: =(E16+F16)/48 | I16: =(D16+E16)/48 | J16: =(D16+G16)/48 | K16: =IF(AND(H16>=0.4,H16<=0.6,I16>=0.4,I16<=0.6,J16>=0.4,J16<=0.6,MIN(D16:G16)>=7.2),"是","否")
A17: 48 组 1 | B17: i7 | C17: 6 | D17: =COUNTIF('384对'!$AB$2:$AB$49,"A") | E17: =COUNTIF('384对'!$AB$2:$AB$49,"C") | F17: =COUNTIF('384对'!$AB$2:$AB$49,"G") | G17: =COUNTIF('384对'!$AB$2:$AB$49,"T") | H17: =(E17+F17)/48 | I17: =(D17+E17)/48 | J17: =(D17+G17)/48 | K17: =IF(AND(H17>=0.4,H17<=0.6,I17>=0.4,I17<=0.6,J17>=0.4,J17<=0.6,MIN(D17:G17)>=7.2),"是","否")
A18: 48 组 1 | B18: i7 | C18: 7 | D18: =COUNTIF('384对'!$AC$2:$AC$49,"A") | E18: =COUNTIF('384对'!$AC$2:$AC$49,"C") | F18: =COUNTIF('384对'!$AC$2:$AC$49,"G") | G18: =COUNTIF('384对'!$AC$2:$AC$49,"T") | H18: =(E18+F18)/48 | I18: =(D18+E18)/48 | J18: =(D18+G18)/48 | K18: =IF(AND(H18>=0.4,H18<=0.6,I18>=0.4,I18<=0.6,J18>=0.4,J18<=0.6,MIN(D18:G18)>=7.2),"是","否")
A19: 48 组 1 | B19: i7 | C19: 8 | D19: =COUNTIF('384对'!$AD$2:$AD$49,"A") | E19: =COUNTIF('384对'!$AD$2:$AD$49,"C") | F19: =COUNTIF('384对'!$AD$2:$AD$49,"G") | G19: =COUNTIF('384对'!$AD$2:$AD$49,"T") | H19: =(E19+F19)/48 | I19: =(D19+E19)/48 | J19: =(D19+G19)/48 | K19: =IF(AND(H19>=0.4,H19<=0.6,I19>=0.4,I19<=0.6,J19>=0.4,J19<=0.6,MIN(D19:G19)>=7.2),"是","否")
A20: 48 组 1 | B20: i7 | C20: 9 | D20: =COUNTIF('384对'!$AE$2:$AE$49,"A") | E20: =COUNTIF('384对'!$AE$2:$AE$49,"C") | F20: =COUNTIF('384对'!$AE$2:$AE$49,"G") | G20: =COUNTIF('384对'!$AE$2:$AE$49,"T") | H20: =(E20+F20)/48 | I20: =(D20+E20)/48 | J20: =(D20+G20)/48 | K20: =IF(AND(H20>=0.4,H20<=0.6,I20>=0.4,I20<=0.6,J20>=0.4,J20<=0.6,MIN(D20:G20)>=7.2),"是","否")
A21: 48 组 1 | B21: i7 | C21: 10 | D21: =COUNTIF('384对'!$AF$2:$AF$49,"A") | E21: =COUNTIF('384对'!$AF$2:$AF$49,"C") | F21: =COUNTIF('384对'!$AF$2:$AF$49,"G") | G21: =COUNTIF('384对'!$AF$2:$AF$49,"T") | H21: =(E21+F21)/48 | I21: =(D21+E21)/48 | J21: =(D21+G21)/48 | K21: =IF(AND(H21>=0.4,H21<=0.6,I21>=0.4,I21<=0.6,J21>=0.4,J21<=0.6,MIN(D21:G21)>=7.2),"是","否")
A22: 48 组 2 | B22: i5 | C22: 1 | D22: =COUNTIF('384对'!$M$50:$M$97,"A") | E22: =COUNTIF('384对'!$M$50:$M$97,"C") | F22: =COUNTIF('384对'!$M$50:$M$97,"G") | G22: =COUNTIF('384对'!$M$50:$M$97,"T") | H22: =(E22+F22)/48 | I22: =(D22+E22)/48 | J22: =(D22+G22)/48 | K22: =IF(AND(H22>=0.4,H22<=0.6,I22>=0.4,I22<=0.6,J22>=0.4,J22<=0.6,MIN(D22:G22)>=7.2),"是","否")
A23: 48 组 2 | B23: i5 | C23: 2 | D23: =COUNTIF('384对'!$N$50:$N$97,"A") | E23: =COUNTIF('384对'!$N$50:$N$97,"C") | F23: =COUNTIF('384对'!$N$50:$N$97,"G") | G23: =COUNTIF('384对'!$N$50:$N$97,"T") | H23: =(E23+F23)/48 | I23: =(D23+E23)/48 | J23: =(D23+G23)/48 | K23: =IF(AND(H23>=0.4,H23<=0.6,I23>=0.4,I23<=0.6,J23>=0.4,J23<=0.6,MIN(D23:G23)>=7.2),"是","否")
A24: 48 组 2 | B24: i5 | C24: 3 | D24: =COUNTIF('384对'!$O$50:$O$97,"A") | E24: =COUNTIF('384对'!$O$50:$O$97,"C") | F24: =COUNTIF('384对'!$O$50:$O$97,"G") | G24: =COUNTIF('384对'!$O$50:$O$97,"T") | H24: =(E24+F24)/48 | I24: =(D24+E24)/48 | J24: =(D24+G24)/48 | K24: =IF(AND(H24>=0.4,H24<=0.6,I24>=0.4,I24<=0.6,J24>=0.4,J24<=0.6,MIN(D24:G24)>=7.2),"是","否")
A25: 48 组 2 | B25: i5 | C25: 4 | D25: =COUNTIF('384对'!$P$50:$P$97,"A") | E25: =COUNTIF('384对'!$P$50:$P$97,"C") | F25: =COUNTIF('384对'!$P$50:$P$97,"G") | G25: =COUNTIF('384对'!$P$50:$P$97,"T") | H25: =(E25+F25)/48 | I25: =(D25+E25)/48 | J25: =(D25+G25)/48 | K25: =IF(AND(H25>=0.4,H25<=0.6,I25>=0.4,I25<=0.6,J25>=0.4,J25<=0.6,MIN(D25:G25)>=7.2),"是","否")
A26: 48 组 2 | B26: i5 | C26: 5 | D26: =COUNTIF('384对'!$Q$50:$Q$97,"A") | E26: =COUNTIF('384对'!$Q$50:$Q$97,"C") | F26: =COUNTIF('384对'!$Q$50:$Q$97,"G") | G26: =COUNTIF('384对'!$Q$50:$Q$97,"T") | H26: =(E26+F26)/48 | I26: =(D26+E26)/48 | J26: =(D26+G26)/48 | K26: =IF(AND(H26>=0.4,H26<=0.6,I26>=0.4,I26<=0.6,J26>=0.4,J26<=0.6,MIN(D26:G26)>=7.2),"是","否")
A27: 48 组 2 | B27: i5 | C27: 6 | D27: =COUNTIF('384对'!$R$50:$R$97,"A") | E27: =COUNTIF('384对'!$R$50:$R$97,"C") | F27: =COUNTIF('384对'!$R$50:$R$97,"G") | G27: =COUNTIF('384对'!$R$50:$R$97,"T") | H27: =(E27+F27)/48 | I27: =(D27+E27)/48 | J27: =(D27+G27)/48 | K27: =IF(AND(H27>=0.4,H27<=0.6,I27>=0.4,I27<=0.6,J27>=0.4,J27<=0.6,MIN(D27:G27)>=7.2),"是","否")
A28: 48 组 2 | B28: i5 | C28: 7 | D28: =COUNTIF('384对'!$S$50:$S$97,"A") | E28: =COUNTIF('384对'!$S$50:$S$97,"C") | F28: =COUNTIF('384对'!$S$50:$S$97,"G") | G28: =COUNTIF('384对'!$S$50:$S$97,"T") | H28: =(E28+F28)/48 | I28: =(D28+E28)/48 | J28: =(D28+G28)/48 | K28: =IF(AND(H28>=0.4,H28<=0.6,I28>=0.4,I28<=0.6,J28>=0.4,J28<=0.6,MIN(D28:G28)>=7.2),"是","否")
A29: 48 组 2 | B29: i5 | C29: 8 | D29: =COUNTIF('384对'!$T$50:$T$97,"A") | E29: =COUNTIF('384对'!$T$50:$T$97,"C") | F29: =COUNTIF('384对'!$T$50:$T$97,"G") | G29: =COUNTIF('384对'!$T$50:$T$97,"T") | H29: =(E29+F29)/48 | I29: =(D29+E29)/48 | J29: =(D29+G29)/48 | K29: =IF(AND(H29>=0.4,H29<=0.6,I29>=0.4,I29<=0.6,J29>=0.4,J29<=0.6,MIN(D29:G29)>=7.2),"是","否")
A30: 48 组 2 | B30: i5 | C30: 9 | D30: =COUNTIF('384对'!$U$50:$U$97,"A") | E30: =COUNTIF('384对'!$U$50:$U$97,"C") | F30: =COUNTIF('384对'!$U$50:$U$97,"G") | G30: =COUNTIF('384对'!$U$50:$U$97,"T") | H30: =(E30+F30)/48 | I30: =(D30+E30)/48 | J30: =(D30+G30)/48 | K30: =IF(AND(H30>=0.4,H30<=0.6,I30>=0.4,I30<=0.6,J30>=0.4,J30<=0.6,MIN(D30:G30)>=7.2),"是","否")
A31: 48 组 2 | B31: i5 | C31: 10 | D31: =COUNTIF('384对'!$V$50:$V$97,"A") | E31: =COUNTIF('384对'!$V$50:$V$97,"C") | F31: =COUNTIF('384对'!$V$50:$V$97,"G") | G31: =COUNTIF('384对'!$V$50:$V$97,"T") | H31: =(E31+F31)/48 | I31: =(D31+E31)/48 | J31: =(D31+G31)/48 | K31: =IF(AND(H31>=0.4,H31<=0.6,I31>=0.4,I31<=0.6,J31>=0.4,J31<=0.6,MIN(D31:G31)>=7.2),"是","否")
A32: 48 组 2 | B32: i7 | C32: 1 | D32: =COUNTIF('384对'!$W$50:$W$97,"A") | E32: =COUNTIF('384对'!$W$50:$W$97,"C") | F32: =COUNTIF('384对'!$W$50:$W$97,"G") | G32: =COUNTIF('384对'!$W$50:$W$97,"T") | H32: =(E32+F32)/48 | I32: =(D32+E32)/48 | J32: =(D32+G32)/48 | K32: =IF(AND(H32>=0.4,H32<=0.6,I32>=0.4,I32<=0.6,J32>=0.4,J32<=0.6,MIN(D32:G32)>=7.2),"是","否")
A33: 48 组 2 | B33: i7 | C33: 2 | D33: =COUNTIF('384对'!$X$50:$X$97,"A") | E33: =COUNTIF('384对'!$X$50:$X$97,"C") | F33: =COUNTIF('384对'!$X$50:$X$97,"G") | G33: =COUNTIF('384对'!$X$50:$X$97,"T") | H33: =(E33+F33)/48 | I33: =(D33+E33)/48 | J33: =(D33+G33)/48 | K33: =IF(AND(H33>=0.4,H33<=0.6,I33>=0.4,I33<=0.6,J33>=0.4,J33<=0.6,MIN(D33:G33)>=7.2),"是","否")
A34: 48 组 2 | B34: i7 | C34: 3 | D34: =COUNTIF('384对'!$Y$50:$Y$97,"A") | E34: =COUNTIF('384对'!$Y$50:$Y$97,"C") | F34: =COUNTIF('384对'!$Y$50:$Y$97,"G") | G34: =COUNTIF('384对'!$Y$50:$Y$97,"T") | H34: =(E34+F34)/48 | I34: =(D34+E34)/48 | J34: =(D34+G34)/48 | K34: =IF(AND(H34>=0.4,H34<=0.6,I34>=0.4,I34<=0.6,J34>=0.4,J34<=0.6,MIN(D34:G34)>=7.2),"是","否")
A35: 48 组 2 | B35: i7 | C35: 4 | D35: =COUNTIF('384对'!$Z$50:$Z$97,"A") | E35: =COUNTIF('384对'!$Z$50:$Z$97,"C") | F35: =COUNTIF('384对'!$Z$50:$Z$97,"G") | G35: =COUNTIF('384对'!$Z$50:$Z$97,"T") | H35: =(E35+F35)/48 | I35: =(D35+E35)/48 | J35: =(D35+G35)/48 | K35: =IF(AND(H35>=0.4,H35<=0.6,I35>=0.4,I35<=0.6,J35>=0.4,J35<=0.6,MIN(D35:G35)>=7.2),"是","否")
A36: 48 组 2 | B36: i7 | C36: 5 | D36: =COUNTIF('384对'!$AA$50:$AA$97,"A") | E36: =COUNTIF('384对'!$AA$50:$AA$97,"C") | F36: =COUNTIF('384对'!$AA$50:$AA$97,"G") | G36: =COUNTIF('384对'!$AA$50:$AA$97,"T") | H36: =(E36+F36)/48 | I36: =(D36+E36)/48 | J36: =(D36+G36)/48 | K36: =IF(AND(H36>=0.4,H36<=0.6,I36>=0.4,I36<=0.6,J36>=0.4,J36<=0.6,MIN(D36:G36)>=7.2),"是","否")
A37: 48 组 2 | B37: i7 | C37: 6 | D37: =COUNTIF('384对'!$AB$50:$AB$97,"A") | E37: =COUNTIF('384对'!$AB$50:$AB$97,"C") | F37: =COUNTIF('384对'!$AB$50:$AB$97,"G") | G37: =COUNTIF('384对'!$AB$50:$AB$97,"T") | H37: =(E37+F37)/48 | I37: =(D37+E37)/48 | J37: =(D37+G37)/48 | K37: =IF(AND(H37>=0.4,H37<=0.6,I37>=0.4,I37<=0.6,J37>=0.4,J37<=0.6,MIN(D37:G37)>=7.2),"是","否")
A38: 48 组 2 | B38: i7 | C38: 7 | D38: =COUNTIF('384对'!$AC$50:$AC$97,"A") | E38: =COUNTIF('384对'!$AC$50:$AC$97,"C") | F38: =COUNTIF('384对'!$AC$50:$AC$97,"G") | G38: =COUNTIF('384对'!$AC$50:$AC$97,"T") | H38: =(E38+F38)/48 | I38: =(D38+E38)/48 | J38: =(D38+G38)/48 | K38: =IF(AND(H38>=0.4,H38<=0.6,I38>=0.4,I38<=0.6,J38>=0.4,J38<=0.6,MIN(D38:G38)>=7.2),"是","否")
A39: 48 组 2 | B39: i7 | C39: 8 | D39: =COUNTIF('384对'!$AD$50:$AD$97,"A") | E39: =COUNTIF('384对'!$AD$50:$AD$97,"C") | F39: =COUNTIF('384对'!$AD$50:$AD$97,"G") | G39: =COUNTIF('384对'!$AD$50:$AD$97,"T") | H39: =(E39+F39)/48 | I39: =(D39+E39)/48 | J39: =(D39+G39)/48 | K39: =IF(AND(H39>=0.4,H39<=0.6,I39>=0.4,I39<=0.6,J39>=0.4,J39<=0.6,MIN(D39:G39)>=7.2),"是","否")
A40: 48 组 2 | B40: i7 | C40: 9 | D40: =COUNTIF('384对'!$AE$50:$AE$97,"A") | E40: =COUNTIF('384对'!$AE$50:$AE$97,"C") | F40: =COUNTIF('384对'!$AE$50:$AE$97,"G") | G40: =COUNTIF('384对'!$AE$50:$AE$97,"T") | H40: =(E40+F40)/48 | I40: =(D40+E40)/48 | J40: =(D40+G40)/48 | K40: =IF(AND(H40>=0.4,H40<=0.6,I40>=0.4,I40<=0.6,J40>=0.4,J40<=0.6,MIN(D40:G40)>=7.2),"是","否")
...
