Workbook

Sheet 说明
A1: 自建 UDP：重新配对后的 96 对（前 48 对 = 核心 48 组）
A2: 做法：960 条自建序列（U001–U960，每条都可当 i5 或 i7）→ 第一阶段单个序列评估 → 第二阶段选 144 个 i5 + 144 个 i7 的候选池（编辑距离 ≥4、跨类反向互补 ≥3、每周期配色达标）→ 第三阶段对 100×100 子集算 i5×i7 的热点正向×反向相互作用 → 第四阶段在子集里选 96 对并配对（前 48 对为核心 48 组）。
A3: 分级来源：预测 96 个管；A：全局二聚体 ≥ −7 且 3′端 ≥ −4.5 kcal/mol；B：≥ −8.5 且 ≥ −5.5；C：其余（经验阈值，无尾巴基线 −5.7 / −3.8）。热点代理的预测与整管评估的一致率在 480 个固定配对管上为 99.6%。
A4: 分级结果：96 组 A 69 / B 27 / C 0；核心 48 组 A 38 / B 10 / C 0。
A5: 96 组独立验证：最小编辑距离（全部序列）=4；跨类 i5 对 rc(i7) 最小编辑距离=3；同一序列与自身反向互补最小=4；每周期全部达标=True；GC范围=(4, 6)；同聚物个数=0；序列数=192；与 Illumina 384 对相同序列数=0
A6: 核心 48 组独立验证：最小编辑距离（全部序列）=4；跨类 i5 对 rc(i7) 最小编辑距离=3；同一序列与自身反向互补最小=4；每周期全部达标=True；GC范围=(4, 6)；同聚物个数=0；序列数=96；与 Illumina 384 对相同序列数=0
A7: 命名：第 n 对的 i5 = DN5{n:03d}（放正向引物 5′端），i7 = DN7{n:03d}（放反向引物 5′端）；“U 编号”是 960 条序列的唯一编号（U001–U480 来自原 i5，U481–U960 来自原 i7，角色可以互换）。
A8: 没有评估的：真实接头；实验验证（建议同样品多条形码对照）。逻辑和代码见 docs/primer_design/udp_denovo960/ 与 python_5R/explore/udp960_*.py。

Sheet 96对
A1: 序号 | B1: 核心48 | C1: i5 名称 | D1: i7 名称 | E1: i5 U编号 | F1: i7 U编号 | G1: i5 序列 | H1: i7 序列 | I1: i5 GC | J1: i7 GC | K1: 分级 | L1: 分级来源 | M1: 全局二聚体最差 ΔG | N1: 3′端最差 ΔG | O1: 发夹最差 ΔG | P1: Olivar 总坏度 | Q1: i5 第1位 | R1: i5 第2位 | S1: i5 第3位 | T1: i5 第4位 | U1: i5 第5位 | V1: i5 第6位 | W1: i5 第7位 | X1: i5 第8位 | Y1: i5 第9位 | Z1: i5 第10位 | AA1: i7 第1位 | AB1: i7 第2位 | AC1: i7 第3位 | AD1: i7 第4位 | AE1: i7 第5位 | AF1: i7 第6位 | AG1: i7 第7位 | AH1: i7 第8位 | AI1: i7 第9位 | AJ1: i7 第10位
A2: 1 | B2: 是 | C2: DN5001 | D2: DN7001 | E2: U898 | F2: U458 | G2: GTAGGAGCGA | H2: GCAGCCTCTT | I2: =LEN(SUBSTITUTE(SUBSTITUTE(G2,"A",""),"T","")) | J2: =LEN(SUBSTITUTE(SUBSTITUTE(H2,"A",""),"T","")) | K2: A | L2: 预测 | M2: -6.68 | N2: -3.46 | Q2: =MID($G2,1,1) | R2: =MID($G2,2,1) | S2: =MID($G2,3,1) | T2: =MID($G2,4,1) | U2: =MID($G2,5,1) | V2: =MID($G2,6,1) | W2: =MID($G2,7,1) | X2: =MID($G2,8,1) | Y2: =MID($G2,9,1) | Z2: =MID($G2,10,1) | AA2: =MID($H2,1,1) | AB2: =MID($H2,2,1) | AC2: =MID($H2,3,1) | AD2: =MID($H2,4,1) | AE2: =MID($H2,5,1) | AF2: =MID($H2,6,1) | AG2: =MID($H2,7,1) | AH2: =MID($H2,8,1) | AI2: =MID($H2,9,1) | AJ2: =MID($H2,10,1)
A3: 2 | B3: 是 | C3: DN5002 | D3: DN7002 | E3: U923 | F3: U257 | G3: AATTCCGGTT | H3: TCTCTAATGC | I3: =LEN(SUBSTITUTE(SUBSTITUTE(G3,"A",""),"T","")) | J3: =LEN(SUBSTITUTE(SUBSTITUTE(H3,"A",""),"T","")) | K3: A | L3: 预测 | M3: -5.91 | N3: -3.79 | Q3: =MID($G3,1,1) | R3: =MID($G3,2,1) | S3: =MID($G3,3,1) | T3: =MID($G3,4,1) | U3: =MID($G3,5,1) | V3: =MID($G3,6,1) | W3: =MID($G3,7,1) | X3: =MID($G3,8,1) | Y3: =MID($G3,9,1) | Z3: =MID($G3,10,1) | AA3: =MID($H3,1,1) | AB3: =MID($H3,2,1) | AC3: =MID($H3,3,1) | AD3: =MID($H3,4,1) | AE3: =MID($H3,5,1) | AF3: =MID($H3,6,1) | AG3: =MID($H3,7,1) | AH3: =MID($H3,8,1) | AI3: =MID($H3,9,1) | AJ3: =MID($H3,10,1)
A4: 3 | B4: 是 | C4: DN5003 | D4: DN7003 | E4: U170 | F4: U573 | G4: ACGCATTCAT | H4: TGTCAATTCG | I4: =LEN(SUBSTITUTE(SUBSTITUTE(G4,"A",""),"T","")) | J4: =LEN(SUBSTITUTE(SUBSTITUTE(H4,"A",""),"T","")) | K4: A | L4: 预测 | M4: -5.93 | N4: -4.17 | Q4: =MID($G4,1,1) | R4: =MID($G4,2,1) | S4: =MID($G4,3,1) | T4: =MID($G4,4,1) | U4: =MID($G4,5,1) | V4: =MID($G4,6,1) | W4: =MID($G4,7,1) | X4: =MID($G4,8,1) | Y4: =MID($G4,9,1) | Z4: =MID($G4,10,1) | AA4: =MID($H4,1,1) | AB4: =MID($H4,2,1) | AC4: =MID($H4,3,1) | AD4: =MID($H4,4,1) | AE4: =MID($H4,5,1) | AF4: =MID($H4,6,1) | AG4: =MID($H4,7,1) | AH4: =MID($H4,8,1) | AI4: =MID($H4,9,1) | AJ4: =MID($H4,10,1)
A5: 4 | B5: 是 | C5: DN5004 | D5: DN7004 | E5: U144 | F5: U505 | G5: TACGGTGAGG | H5: GAAGGACGTC | I5: =LEN(SUBSTITUTE(SUBSTITUTE(G5,"A",""),"T","")) | J5: =LEN(SUBSTITUTE(SUBSTITUTE(H5,"A",""),"T","")) | K5: A | L5: 预测 | M5: -6.6 | N5: -3.96 | Q5: =MID($G5,1,1) | R5: =MID($G5,2,1) | S5: =MID($G5,3,1) | T5: =MID($G5,4,1) | U5: =MID($G5,5,1) | V5: =MID($G5,6,1) | W5: =MID($G5,7,1) | X5: =MID($G5,8,1) | Y5: =MID($G5,9,1) | Z5: =MID($G5,10,1) | AA5: =MID($H5,1,1) | AB5: =MID($H5,2,1) | AC5: =MID($H5,3,1) | AD5: =MID($H5,4,1) | AE5: =MID($H5,5,1) | AF5: =MID($H5,6,1) | AG5: =MID($H5,7,1) | AH5: =MID($H5,8,1) | AI5: =MID($H5,9,1) | AJ5: =MID($H5,10,1)
A6: 5 | B6: 是 | C6: DN5005 | D6: DN7005 | E6: U664 | F6: U491 | G6: AATCTCCGAA | H6: TGGATGTCCG | I6: =LEN(SUBSTITUTE(SUBSTITUTE(G6,"A",""),"T","")) | J6: =LEN(SUBSTITUTE(SUBSTITUTE(H6,"A",""),"T","")) | K6: A | L6: 预测 | M6: -6.85 | N6: -3.31 | Q6: =MID($G6,1,1) | R6: =MID($G6,2,1) | S6: =MID($G6,3,1) | T6: =MID($G6,4,1) | U6: =MID($G6,5,1) | V6: =MID($G6,6,1) | W6: =MID($G6,7,1) | X6: =MID($G6,8,1) | Y6: =MID($G6,9,1) | Z6: =MID($G6,10,1) | AA6: =MID($H6,1,1) | AB6: =MID($H6,2,1) | AC6: =MID($H6,3,1) | AD6: =MID($H6,4,1) | AE6: =MID($H6,5,1) | AF6: =MID($H6,6,1) | AG6: =MID($H6,7,1) | AH6: =MID($H6,8,1) | AI6: =MID($H6,9,1) | AJ6: =MID($H6,10,1)
A7: 6 | B7: 是 | C7: DN5006 | D7: DN7006 | E7: U675 | F7: U290 | G7: GACACTCGAG | H7: AGGTCGTCCA | I7: =LEN(SUBSTITUTE(SUBSTITUTE(G7,"A",""),"T","")) | J7: =LEN(SUBSTITUTE(SUBSTITUTE(H7,"A",""),"T","")) | K7: A | L7: 预测 | M7: -6.77 | N7: -4.47 | Q7: =MID($G7,1,1) | R7: =MID($G7,2,1) | S7: =MID($G7,3,1) | T7: =MID($G7,4,1) | U7: =MID($G7,5,1) | V7: =MID($G7,6,1) | W7: =MID($G7,7,1) | X7: =MID($G7,8,1) | Y7: =MID($G7,9,1) | Z7: =MID($G7,10,1) | AA7: =MID($H7,1,1) | AB7: =MID($H7,2,1) | AC7: =MID($H7,3,1) | AD7: =MID($H7,4,1) | AE7: =MID($H7,5,1) | AF7: =MID($H7,6,1) | AG7: =MID($H7,7,1) | AH7: =MID($H7,8,1) | AI7: =MID($H7,9,1) | AJ7: =MID($H7,10,1)
A8: 7 | B8: 是 | C8: DN5007 | D8: DN7007 | E8: U496 | F8: U134 | G8: CGCATAAGGT | H8: GCCTGGTGTA | I8: =LEN(SUBSTITUTE(SUBSTITUTE(G8,"A",""),"T","")) | J8: =LEN(SUBSTITUTE(SUBSTITUTE(H8,"A",""),"T","")) | K8: A | L8: 预测 | M8: -6.1 | N8: -4.04 | Q8: =MID($G8,1,1) | R8: =MID($G8,2,1) | S8: =MID($G8,3,1) | T8: =MID($G8,4,1) | U8: =MID($G8,5,1) | V8: =MID($G8,6,1) | W8: =MID($G8,7,1) | X8: =MID($G8,8,1) | Y8: =MID($G8,9,1) | Z8: =MID($G8,10,1) | AA8: =MID($H8,1,1) | AB8: =MID($H8,2,1) | AC8: =MID($H8,3,1) | AD8: =MID($H8,4,1) | AE8: =MID($H8,5,1) | AF8: =MID($H8,6,1) | AG8: =MID($H8,7,1) | AH8: =MID($H8,8,1) | AI8: =MID($H8,9,1) | AJ8: =MID($H8,10,1)
A9: 8 | B9: 是 | C9: DN5008 | D9: DN7008 | E9: U555 | F9: U821 | G9: AGCTGCGCAA | H9: CTGAGAACCA | I9: =LEN(SUBSTITUTE(SUBSTITUTE(G9,"A",""),"T","")) | J9: =LEN(SUBSTITUTE(SUBSTITUTE(H9,"A",""),"T","")) | K9: A | L9: 预测 | M9: -6.64 | N9: -3.44 | Q9: =MID($G9,1,1) | R9: =MID($G9,2,1) | S9: =MID($G9,3,1) | T9: =MID($G9,4,1) | U9: =MID($G9,5,1) | V9: =MID($G9,6,1) | W9: =MID($G9,7,1) | X9: =MID($G9,8,1) | Y9: =MID($G9,9,1) | Z9: =MID($G9,10,1) | AA9: =MID($H9,1,1) | AB9: =MID($H9,2,1) | AC9: =MID($H9,3,1) | AD9: =MID($H9,4,1) | AE9: =MID($H9,5,1) | AF9: =MID($H9,6,1) | AG9: =MID($H9,7,1) | AH9: =MID($H9,8,1) | AI9: =MID($H9,9,1) | AJ9: =MID($H9,10,1)
A10: 9 | B10: 是 | C10: DN5009 | D10: DN7009 | E10: U798 | F10: U344 | G10: TCAGACGTTA | H10: CTCGATCACG | I10: =LEN(SUBSTITUTE(SUBSTITUTE(G10,"A",""),"T","")) | J10: =LEN(SUBSTITUTE(SUBSTITUTE(H10,"A",""),"T","")) | K10: A | L10: 预测 | M10: -6.33 | N10: -3.01 | Q10: =MID($G10,1,1) | R10: =MID($G10,2,1) | S10: =MID($G10,3,1) | T10: =MID($G10,4,1) | U10: =MID($G10,5,1) | V10: =MID($G10,6,1) | W10: =MID($G10,7,1) | X10: =MID($G10,8,1) | Y10: =MID($G10,9,1) | Z10: =MID($G10,10,1) | AA10: =MID($H10,1,1) | AB10: =MID($H10,2,1) | AC10: =MID($H10,3,1) | AD10: =MID($H10,4,1) | AE10: =MID($H10,5,1) | AF10: =MID($H10,6,1) | AG10: =MID($H10,7,1) | AH10: =MID($H10,8,1) | AI10: =MID($H10,9,1) | AJ10: =MID($H10,10,1)
A11: 10 | B11: 是 | C11: DN5010 | D11: DN7010 | E11: U677 | F11: U414 | G11: CAAGACTCTA | H11: GAACTTACAG | I11: =LEN(SUBSTITUTE(SUBSTITUTE(G11,"A",""),"T","")) | J11: =LEN(SUBSTITUTE(SUBSTITUTE(H11,"A",""),"T","")) | K11: A | L11: 预测 | M11: -6.27 | N11: -4.05 | Q11: =MID($G11,1,1) | R11: =MID($G11,2,1) | S11: =MID($G11,3,1) | T11: =MID($G11,4,1) | U11: =MID($G11,5,1) | V11: =MID($G11,6,1) | W11: =MID($G11,7,1) | X11: =MID($G11,8,1) | Y11: =MID($G11,9,1) | Z11: =MID($G11,10,1) | AA11: =MID($H11,1,1) | AB11: =MID($H11,2,1) | AC11: =MID($H11,3,1) | AD11: =MID($H11,4,1) | AE11: =MID($H11,5,1) | AF11: =MID($H11,6,1) | AG11: =MID($H11,7,1) | AH11: =MID($H11,8,1) | AI11: =MID($H11,9,1) | AJ11: =MID($H11,10,1)
A12: 11 | B12: 是 | C12: DN5011 | D12: DN7011 | E12: U725 | F12: U341 | G12: GTGCGTTACC | H12: CTTGGTGTTG | I12: =LEN(SUBSTITUTE(SUBSTITUTE(G12,"A",""),"T","")) | J12: =LEN(SUBSTITUTE(SUBSTITUTE(H12,"A",""),"T","")) | K12: B | L12: 预测 | M12: -6.44 | N12: -5.05 | Q12: =MID($G12,1,1) | R12: =MID($G12,2,1) | S12: =MID($G12,3,1) | T12: =MID($G12,4,1) | U12: =MID($G12,5,1) | V12: =MID($G12,6,1) | W12: =MID($G12,7,1) | X12: =MID($G12,8,1) | Y12: =MID($G12,9,1) | Z12: =MID($G12,10,1) | AA12: =MID($H12,1,1) | AB12: =MID($H12,2,1) | AC12: =MID($H12,3,1) | AD12: =MID($H12,4,1) | AE12: =MID($H12,5,1) | AF12: =MID($H12,6,1) | AG12: =MID($H12,7,1) | AH12: =MID($H12,8,1) | AI12: =MID($H12,9,1) | AJ12: =MID($H12,10,1)
A13: 12 | B13: 是 | C13: DN5012 | D13: DN7012 | E13: U723 | F13: U878 | G13: CTCTCGCTGT | H13: TAACTGAAGC | I13: =LEN(SUBSTITUTE(SUBSTITUTE(G13,"A",""),"T","")) | J13: =LEN(SUBSTITUTE(SUBSTITUTE(H13,"A",""),"T","")) | K13: A | L13: 预测 | M13: -6.06 | N13: -3.9 | Q13: =MID($G13,1,1) | R13: =MID($G13,2,1) | S13: =MID($G13,3,1) | T13: =MID($G13,4,1) | U13: =MID($G13,5,1) | V13: =MID($G13,6,1) | W13: =MID($G13,7,1) | X13: =MID($G13,8,1) | Y13: =MID($G13,9,1) | Z13: =MID($G13,10,1) | AA13: =MID($H13,1,1) | AB13: =MID($H13,2,1) | AC13: =MID($H13,3,1) | AD13: =MID($H13,4,1) | AE13: =MID($H13,5,1) | AF13: =MID($H13,6,1) | AG13: =MID($H13,7,1) | AH13: =MID($H13,8,1) | AI13: =MID($H13,9,1) | AJ13: =MID($H13,10,1)
... A49: 48 | B49: 是 | C49: DN5048 | D49: DN7048 | E49: U353 | F49: U245 | G49: GCCTGAACTC | H49: CTTGCCAACT | I49: =LEN(SUBSTITUTE(SUBSTITUTE(G49,"A",""),"T","")) | J49: =LEN(SUBSTITUTE(SUBSTITUTE(H49,"A",""),"T","")) | K49: B | L49: 预测 | M49: -6.73 | N49: -4.7 | Q49: =MID($G49,1,1) | R49: =MID($G49,2,1) | S49: =MID($G49,3,1) | T49: =MID($G49,4,1) | U49: =MID($G49,5,1) | V49: =MID($G49,6,1) | W49: =MID($G49,7,1) | X49: =MID($G49,8,1) | Y49: =MID($G49,9,1) | Z49: =MID($G49,10,1) | AA49: =MID($H49,1,1) | AB49: =MID($H49,2,1) | AC49: =MID($H49,3,1) | AD49: =MID($H49,4,1) | AE49: =MID($H49,5,1) | AF49: =MID($H49,6,1) | AG49: =MID($H49,7,1) | AH49: =MID($H49,8,1) | AI49: =MID($H49,9,1) | AJ49: =MID($H49,10,1)
A50: 49 | C50: DN5049 | D50: DN7049 | E50: U852 | F50: U308 | G50: AATCCGACAA | H50: CCAGGAGATG | I50: =LEN(SUBSTITUTE(SUBSTITUTE(G50,"A",""),"T","")) | J50: =LEN(SUBSTITUTE(SUBSTITUTE(H50,"A",""),"T","")) | K50: A | L50: 预测 | M50: -6.93 | N50: -3.8 | Q50: =MID($G50,1,1) | R50: =MID($G50,2,1) | S50: =MID($G50,3,1) | T50: =MID($G50,4,1) | U50: =MID($G50,5,1) | V50: =MID($G50,6,1) | W50: =MID($G50,7,1) | X50: =MID($G50,8,1) | Y50: =MID($G50,9,1) | Z50: =MID($G50,10,1) | AA50: =MID($H50,1,1) | AB50: =MID($H50,2,1) | AC50: =MID($H50,3,1) | AD50: =MID($H50,4,1) | AE50: =MID($H50,5,1) | AF50: =MID($H50,6,1) | AG50: =MID($H50,7,1) | AH50: =MID($H50,8,1) | AI50: =MID($H50,9,1) | AJ50: =MID($H50,10,1)
A51: 50 | C51: DN5050 | D51: DN7050 | E51: U089 | F51: U594 | G51: CTCTGTCGGA | H51: CGCAGGACTT | I51: =LEN(SUBSTITUTE(SUBSTITUTE(G51,"A",""),"T","")) | J51: =LEN(SUBSTITUTE(SUBSTITUTE(H51,"A",""),"T","")) | K51: A | L51: 预测 | M51: -5.74 | N51: -3.32 | Q51: =MID($G51,1,1) | R51: =MID($G51,2,1) | S51: =MID($G51,3,1) | T51: =MID($G51,4,1) | U51: =MID($G51,5,1) | V51: =MID($G51,6,1) | W51: =MID($G51,7,1) | X51: =MID($G51,8,1) | Y51: =MID($G51,9,1) | Z51: =MID($G51,10,1) | AA51: =MID($H51,1,1) | AB51: =MID($H51,2,1) | AC51: =MID($H51,3,1) | AD51: =MID($H51,4,1) | AE51: =MID($H51,5,1) | AF51: =MID($H51,6,1) | AG51: =MID($H51,7,1) | AH51: =MID($H51,8,1) | AI51: =MID($H51,9,1) | AJ51: =MID($H51,10,1)
A52: 51 | C52: DN5051 | D52: DN7051 | E52: U666 | F52: U190 | G52: CTTACACCTC | H52: GCAAGCCAAC | I52: =LEN(SUBSTITUTE(SUBSTITUTE(G52,"A",""),"T","")) | J52: =LEN(SUBSTITUTE(SUBSTITUTE(H52,"A",""),"T","")) | K52: B | L52: 预测 | M52: -5.74 | N52: -4.7 | Q52: =MID($G52,1,1) | R52: =MID($G52,2,1) | S52: =MID($G52,3,1) | T52: =MID($G52,4,1) | U52: =MID($G52,5,1) | V52: =MID($G52,6,1) | W52: =MID($G52,7,1) | X52: =MID($G52,8,1) | Y52: =MID($G52,9,1) | Z52: =MID($G52,10,1) | AA52: =MID($H52,1,1) | AB52: =MID($H52,2,1) | AC52: =MID($H52,3,1) | AD52: =MID($H52,4,1) | AE52: =MID($H52,5,1) | AF52: =MID($H52,6,1) | AG52: =MID($H52,7,1) | AH52: =MID($H52,8,1) | AI52: =MID($H52,9,1) | AJ52: =MID($H52,10,1)
A53: 52 | C53: DN5052 | D53: DN7052 | E53: U094 | F53: U185 | G53: AGTCAAGAGT | H53: GACGACCTCA | I53: =LEN(SUBSTITUTE(SUBSTITUTE(G53,"A",""),"T","")) | J53: =LEN(SUBSTITUTE(SUBSTITUTE(H53,"A",""),"T","")) | K53: A | L53: 预测 | M53: -6.1 | N53: -3.79 | Q53: =MID($G53,1,1) | R53: =MID($G53,2,1) | S53: =MID($G53,3,1) | T53: =MID($G53,4,1) | U53: =MID($G53,5,1) | V53: =MID($G53,6,1) | W53: =MID($G53,7,1) | X53: =MID($G53,8,1) | Y53: =MID($G53,9,1) | Z53: =MID($G53,10,1) | AA53: =MID($H53,1,1) | AB53: =MID($H53,2,1) | AC53: =MID($H53,3,1) | AD53: =MID($H53,4,1) | AE53: =MID($H53,5,1) | AF53: =MID($H53,6,1) | AG53: =MID($H53,7,1) | AH53: =MID($H53,8,1) | AI53: =MID($H53,9,1) | AJ53: =MID($H53,10,1)
A54: 53 | C54: DN5053 | D54: DN7053 | E54: U752 | F54: U727 | G54: CAGGAGGCAA | H54: GTGTCCGTTG | I54: =LEN(SUBSTITUTE(SUBSTITUTE(G54,"A",""),"T","")) | J54: =LEN(SUBSTITUTE(SUBSTITUTE(H54,"A",""),"T","")) | K54: A | L54: 预测 | M54: -6.27 | N54: -4.26 | Q54: =MID($G54,1,1) | R54: =MID($G54,2,1) | S54: =MID($G54,3,1) | T54: =MID($G54,4,1) | U54: =MID($G54,5,1) | V54: =MID($G54,6,1) | W54: =MID($G54,7,1) | X54: =MID($G54,8,1) | Y54: =MID($G54,9,1) | Z54: =MID($G54,10,1) | AA54: =MID($H54,1,1) | AB54: =MID($H54,2,1) | AC54: =MID($H54,3,1) | AD54: =MID($H54,4,1) | AE54: =MID($H54,5,1) | AF54: =MID($H54,6,1) | AG54: =MID($H54,7,1) | AH54: =MID($H54,8,1) | AI54: =MID($H54,9,1) | AJ54: =MID($H54,10,1)
A55: 54 | C55: DN5054 | D55: DN7054 | E55: U157 | F55: U122 | G55: TGGCATTAGA | H55: GCTAACCTCC | I55: =LEN(SUBSTITUTE(SUBSTITUTE(G55,"A",""),"T","")) | J55: =LEN(SUBSTITUTE(SUBSTITUTE(H55,"A",""),"T","")) | K55: A | L55: 预测 | M55: -6.03 | N55: -2.37 | Q55: =MID($G55,1,1) | R55: =MID($G55,2,1) | S55: =MID($G55,3,1) | T55: =MID($G55,4,1) | U55: =MID($G55,5,1) | V55: =MID($G55,6,1) | W55: =MID($G55,7,1) | X55: =MID($G55,8,1) | Y55: =MID($G55,9,1) | Z55: =MID($G55,10,1) | AA55: =MID($H55,1,1) | AB55: =MID($H55,2,1) | AC55: =MID($H55,3,1) | AD55: =MID($H55,4,1) | AE55: =MID($H55,5,1) | AF55: =MID($H55,6,1) | AG55: =MID($H55,7,1) | AH55: =MID($H55,8,1) | AI55: =MID($H55,9,1) | AJ55: =MID($H55,10,1)
A56: 55 | C56: DN5055 | D56: DN7055 | E56: U743 | F56: U078 | G56: ATCAGACATG | H56: AGGACACCAC | I56: =LEN(SUBSTITUTE(SUBSTITUTE(G56,"A",""),"T","")) | J56: =LEN(SUBSTITUTE(SUBSTITUTE(H56,"A",""),"T","")) | K56: B | L56: 预测 | M56: -8.16 | N56: -3.51 | Q56: =MID($G56,1,1) | R56: =MID($G56,2,1) | S56: =MID($G56,3,1) | T56: =MID($G56,4,1) | U56: =MID($G56,5,1) | V56: =MID($G56,6,1) | W56: =MID($G56,7,1) | X56: =MID($G56,8,1) | Y56: =MID($G56,9,1) | Z56: =MID($G56,10,1) | AA56: =MID($H56,1,1) | AB56: =MID($H56,2,1) | AC56: =MID($H56,3,1) | AD56: =MID($H56,4,1) | AE56: =MID($H56,5,1) | AF56: =MID($H56,6,1) | AG56: =MID($H56,7,1) | AH56: =MID($H56,8,1) | AI56: =MID($H56,9,1) | AJ56: =MID($H56,10,1)
A57: 56 | C57: DN5056 | D57: DN7056 | E57: U669 | F57: U930 | G57: ATTAGCCTGA | H57: AGGATTACTC | I57: =LEN(SUBSTITUTE(SUBSTITUTE(G57,"A",""),"T","")) | J57: =LEN(SUBSTITUTE(SUBSTITUTE(H57,"A",""),"T","")) | K57: A | L57: 预测 | M57: -6.85 | N57: -3.8 | Q57: =MID($G57,1,1) | R57: =MID($G57,2,1) | S57: =MID($G57,3,1) | T57: =MID($G57,4,1) | U57: =MID($G57,5,1) | V57: =MID($G57,6,1) | W57: =MID($G57,7,1) | X57: =MID($G57,8,1) | Y57: =MID($G57,9,1) | Z57: =MID($G57,10,1) | AA57: =MID($H57,1,1) | AB57: =MID($H57,2,1) | AC57: =MID($H57,3,1) | AD57: =MID($H57,4,1) | AE57: =MID($H57,5,1) | AF57: =MID($H57,6,1) | AG57: =MID($H57,7,1) | AH57: =MID($H57,8,1) | AI57: =MID($H57,9,1) | AJ57: =MID($H57,10,1)
A58: 57 | C58: DN5057 | D58: DN7057 | E58: U953 | F58: U337 | G58: ATTCTGTTCC | H58: GCTCCATAAG | I58: =LEN(SUBSTITUTE(SUBSTITUTE(G58,"A",""),"T","")) | J58: =LEN(SUBSTITUTE(SUBSTITUTE(H58,"A",""),"T","")) | K58: B | L58: 预测 | M58: -5.86 | N58: -4.54 | Q58: =MID($G58,1,1) | R58: =MID($G58,2,1) | S58: =MID($G58,3,1) | T58: =MID($G58,4,1) | U58: =MID($G58,5,1) | V58: =MID($G58,6,1) | W58: =MID($G58,7,1) | X58: =MID($G58,8,1) | Y58: =MID($G58,9,1) | Z58: =MID($G58,10,1) | AA58: =MID($H58,1,1) | AB58: =MID($H58,2,1) | AC58: =MID($H58,3,1) | AD58: =MID($H58,4,1) | AE58: =MID($H58,5,1) | AF58: =MID($H58,6,1) | AG58: =MID($H58,7,1) | AH58: =MID($H58,8,1) | AI58: =MID($H58,9,1) | AJ58: =MID($H58,10,1)
A59: 58 | C59: DN5058 | D59: DN7058 | E59: U467 | F59: U934 | G59: GAGCAACGGT | H59: ACATTCTAGC | I59: =LEN(SUBSTITUTE(SUBSTITUTE(G59,"A",""),"T","")) | J59: =LEN(SUBSTITUTE(SUBSTITUTE(H59,"A",""),"T","")) | K59: A | L59: 预测 | M59: -6.06 | N59: -3.79 | Q59: =MID($G59,1,1) | R59: =MID($G59,2,1) | S59: =MID($G59,3,1) | T59: =MID($G59,4,1) | U59: =MID($G59,5,1) | V59: =MID($G59,6,1) | W59: =MID($G59,7,1) | X59: =MID($G59,8,1) | Y59: =MID($G59,9,1) | Z59: =MID($G59,10,1) | AA59: =MID($H59,1,1) | AB59: =MID($H59,2,1) | AC59: =MID($H59,3,1) | AD59: =MID($H59,4,1) | AE59: =MID($H59,5,1) | AF59: =MID($H59,6,1) | AG59: =MID($H59,7,1) | AH59: =MID($H59,8,1) | AI59: =MID($H59,9,1) | AJ59: =MID($H59,10,1)
A60: 59 | C60: DN5059 | D60: DN7059 | E60: U084 | F60: U095 | G60: CCACCACTAT | H60: TCGCGTGAAC | I60: =LEN(SUBSTITUTE(SUBSTITUTE(G60,"A",""),"T","")) | J60: =LEN(SUBSTITUTE(SUBSTITUTE(H60,"A",""),"T","")) | K60: A | L60: 预测 | M60: -5.74 | N60: -4.17 | Q60: =MID($G60,1,1) | R60: =MID($G60,2,1) | S60: =MID($G60,3,1) | T60: =MID($G60,4,1) | U60: =MID($G60,5,1) | V60: =MID($G60,6,1) | W60: =MID($G60,7,1) | X60: =MID($G60,8,1) | Y60: =MID($G60,9,1) | Z60: =MID($G60,10,1) | AA60: =MID($H60,1,1) | AB60: =MID($H60,2,1) | AC60: =MID($H60,3,1) | AD60: =MID($H60,4,1) | AE60: =MID($H60,5,1) | AF60: =MID($H60,6,1) | AG60: =MID($H60,7,1) | AH60: =MID($H60,8,1) | AI60: =MID($H60,9,1) | AJ60: =MID($H60,10,1)
A61: 60 | C61: DN5060 | D61: DN7060 | E61: U370 | F61: U706 | G61: CCAGCGCATA | H61: AGTTCCAACA | I61: =LEN(SUBSTITUTE(SUBSTITUTE(G61,"A",""),"T","")) | J61: =LEN(SUBSTITUTE(SUBSTITUTE(H61,"A",""),"T","")) | K61: A | L61: 预测 | M61: -6.44 | N61: -3.66 | Q61: =MID($G61,1,1) | R61: =MID($G61,2,1) | S61: =MID($G61,3,1) | T61: =MID($G61,4,1) | U61: =MID($G61,5,1) | V61: =MID($G61,6,1) | W61: =MID($G61,7,1) | X61: =MID($G61,8,1) | Y61: =MID($G61,9,1) | Z61: =MID($G61,10,1) | AA61: =MID($H61,1,1) | AB61: =MID($H61,2,1) | AC61: =MID($H61,3,1) | AD61: =MID($H61,4,1) | AE61: =MID($H61,5,1) | AF61: =MID($H61,6,1) | AG61: =MID($H61,7,1) | AH61: =MID($H61,8,1) | AI61: =MID($H61,9,1) | AJ61: =MID($H61,10,1)
... A97: 96 | C97: DN5096 | D97: DN7096 | E97: U242 | F97: U546 | G97: GAACCGCCTT | H97: GCGGTGAGTT | I97: =LEN(SUBSTITUTE(SUBSTITUTE(G97,"A",""),"T","")) | J97: =LEN(SUBSTITUTE(SUBSTITUTE(H97,"A",""),"T","")) | K97: A | L97: 预测 | M97: -6.31 | N97: -3.79 | Q97: =MID($G97,1,1) | R97: =MID($G97,2,1) | S97: =MID($G97,3,1) | T97: =MID($G97,4,1) | U97: =MID($G97,5,1) | V97: =MID($G97,6,1) | W97: =MID($G97,7,1) | X97: =MID($G97,8,1) | Y97: =MID($G97,9,1) | Z97: =MID($G97,10,1) | AA97: =MID($H97,1,1) | AB97: =MID($H97,2,1) | AC97: =MID($H97,3,1) | AD97: =MID($H97,4,1) | AE97: =MID($H97,5,1) | AF97: =MID($H97,6,1) | AG97: =MID($H97,7,1) | AH97: =MID($H97,8,1) | AI97: =MID($H97,9,1) | AJ97: =MID($H97,10,1)

Sheet 每周期统计
A1: 范围 | B1: 序列 | C1: 周期 | D1: A | E1: C | F1: G | G1: T | H1: GC% | I1: A+C% | J1: A+T% | K1: 是否达标
A2: 96 组 | B2: i5 | C2: 1 | D2: =COUNTIF('96对'!$Q$2:$Q$97,"A") | E2: =COUNTIF('96对'!$Q$2:$Q$97,"C") | F2: =COUNTIF('96对'!$Q$2:$Q$97,"G") | G2: =COUNTIF('96对'!$Q$2:$Q$97,"T") | H2: =(E2+F2)/96 | I2: =(D2+E2)/96 | J2: =(D2+G2)/96 | K2: =IF(AND(H2>=0.4,H2<=0.6,I2>=0.4,I2<=0.6,J2>=0.4,J2<=0.6,MIN(D2:G2)>=14.4),"是","否")
A3: 96 组 | B3: i5 | C3: 2 | D3: =COUNTIF('96对'!$R$2:$R$97,"A") | E3: =COUNTIF('96对'!$R$2:$R$97,"C") | F3: =COUNTIF('96对'!$R$2:$R$97,"G") | G3: =COUNTIF('96对'!$R$2:$R$97,"T") | H3: =(E3+F3)/96 | I3: =(D3+E3)/96 | J3: =(D3+G3)/96 | K3: =IF(AND(H3>=0.4,H3<=0.6,I3>=0.4,I3<=0.6,J3>=0.4,J3<=0.6,MIN(D3:G3)>=14.4),"是","否")
A4: 96 组 | B4: i5 | C4: 3 | D4: =COUNTIF('96对'!$S$2:$S$97,"A") | E4: =COUNTIF('96对'!$S$2:$S$97,"C") | F4: =COUNTIF('96对'!$S$2:$S$97,"G") | G4: =COUNTIF('96对'!$S$2:$S$97,"T") | H4: =(E4+F4)/96 | I4: =(D4+E4)/96 | J4: =(D4+G4)/96 | K4: =IF(AND(H4>=0.4,H4<=0.6,I4>=0.4,I4<=0.6,J4>=0.4,J4<=0.6,MIN(D4:G4)>=14.4),"是","否")
A5: 96 组 | B5: i5 | C5: 4 | D5: =COUNTIF('96对'!$T$2:$T$97,"A") | E5: =COUNTIF('96对'!$T$2:$T$97,"C") | F5: =COUNTIF('96对'!$T$2:$T$97,"G") | G5: =COUNTIF('96对'!$T$2:$T$97,"T") | H5: =(E5+F5)/96 | I5: =(D5+E5)/96 | J5: =(D5+G5)/96 | K5: =IF(AND(H5>=0.4,H5<=0.6,I5>=0.4,I5<=0.6,J5>=0.4,J5<=0.6,MIN(D5:G5)>=14.4),"是","否")
A6: 96 组 | B6: i5 | C6: 5 | D6: =COUNTIF('96对'!$U$2:$U$97,"A") | E6: =COUNTIF('96对'!$U$2:$U$97,"C") | F6: =COUNTIF('96对'!$U$2:$U$97,"G") | G6: =COUNTIF('96对'!$U$2:$U$97,"T") | H6: =(E6+F6)/96 | I6: =(D6+E6)/96 | J6: =(D6+G6)/96 | K6: =IF(AND(H6>=0.4,H6<=0.6,I6>=0.4,I6<=0.6,J6>=0.4,J6<=0.6,MIN(D6:G6)>=14.4),"是","否")
A7: 96 组 | B7: i5 | C7: 6 | D7: =COUNTIF('96对'!$V$2:$V$97,"A") | E7: =COUNTIF('96对'!$V$2:$V$97,"C") | F7: =COUNTIF('96对'!$V$2:$V$97,"G") | G7: =COUNTIF('96对'!$V$2:$V$97,"T") | H7: =(E7+F7)/96 | I7: =(D7+E7)/96 | J7: =(D7+G7)/96 | K7: =IF(AND(H7>=0.4,H7<=0.6,I7>=0.4,I7<=0.6,J7>=0.4,J7<=0.6,MIN(D7:G7)>=14.4),"是","否")
A8: 96 组 | B8: i5 | C8: 7 | D8: =COUNTIF('96对'!$W$2:$W$97,"A") | E8: =COUNTIF('96对'!$W$2:$W$97,"C") | F8: =COUNTIF('96对'!$W$2:$W$97,"G") | G8: =COUNTIF('96对'!$W$2:$W$97,"T") | H8: =(E8+F8)/96 | I8: =(D8+E8)/96 | J8: =(D8+G8)/96 | K8: =IF(AND(H8>=0.4,H8<=0.6,I8>=0.4,I8<=0.6,J8>=0.4,J8<=0.6,MIN(D8:G8)>=14.4),"是","否")
A9: 96 组 | B9: i5 | C9: 8 | D9: =COUNTIF('96对'!$X$2:$X$97,"A") | E9: =COUNTIF('96对'!$X$2:$X$97,"C") | F9: =COUNTIF('96对'!$X$2:$X$97,"G") | G9: =COUNTIF('96对'!$X$2:$X$97,"T") | H9: =(E9+F9)/96 | I9: =(D9+E9)/96 | J9: =(D9+G9)/96 | K9: =IF(AND(H9>=0.4,H9<=0.6,I9>=0.4,I9<=0.6,J9>=0.4,J9<=0.6,MIN(D9:G9)>=14.4),"是","否")
A10: 96 组 | B10: i5 | C10: 9 | D10: =COUNTIF('96对'!$Y$2:$Y$97,"A") | E10: =COUNTIF('96对'!$Y$2:$Y$97,"C") | F10: =COUNTIF('96对'!$Y$2:$Y$97,"G") | G10: =COUNTIF('96对'!$Y$2:$Y$97,"T") | H10: =(E10+F10)/96 | I10: =(D10+E10)/96 | J10: =(D10+G10)/96 | K10: =IF(AND(H10>=0.4,H10<=0.6,I10>=0.4,I10<=0.6,J10>=0.4,J10<=0.6,MIN(D10:G10)>=14.4),"是","否")
A11: 96 组 | B11: i5 | C11: 10 | D11: =COUNTIF('96对'!$Z$2:$Z$97,"A") | E11: =COUNTIF('96对'!$Z$2:$Z$97,"C") | F11: =COUNTIF('96对'!$Z$2:$Z$97,"G") | G11: =COUNTIF('96对'!$Z$2:$Z$97,"T") | H11: =(E11+F11)/96 | I11: =(D11+E11)/96 | J11: =(D11+G11)/96 | K11: =IF(AND(H11>=0.4,H11<=0.6,I11>=0.4,I11<=0.6,J11>=0.4,J11<=0.6,MIN(D11:G11)>=14.4),"是","否")
A12: 96 组 | B12: i7 | C12: 1 | D12: =COUNTIF('96对'!$AA$2:$AA$97,"A") | E12: =COUNTIF('96对'!$AA$2:$AA$97,"C") | F12: =COUNTIF('96对'!$AA$2:$AA$97,"G") | G12: =COUNTIF('96对'!$AA$2:$AA$97,"T") | H12: =(E12+F12)/96 | I12: =(D12+E12)/96 | J12: =(D12+G12)/96 | K12: =IF(AND(H12>=0.4,H12<=0.6,I12>=0.4,I12<=0.6,J12>=0.4,J12<=0.6,MIN(D12:G12)>=14.4),"是","否")
A13: 96 组 | B13: i7 | C13: 2 | D13: =COUNTIF('96对'!$AB$2:$AB$97,"A") | E13: =COUNTIF('96对'!$AB$2:$AB$97,"C") | F13: =COUNTIF('96对'!$AB$2:$AB$97,"G") | G13: =COUNTIF('96对'!$AB$2:$AB$97,"T") | H13: =(E13+F13)/96 | I13: =(D13+E13)/96 | J13: =(D13+G13)/96 | K13: =IF(AND(H13>=0.4,H13<=0.6,I13>=0.4,I13<=0.6,J13>=0.4,J13<=0.6,MIN(D13:G13)>=14.4),"是","否")
A14: 96 组 | B14: i7 | C14: 3 | D14: =COUNTIF('96对'!$AC$2:$AC$97,"A") | E14: =COUNTIF('96对'!$AC$2:$AC$97,"C") | F14: =COUNTIF('96对'!$AC$2:$AC$97,"G") | G14: =COUNTIF('96对'!$AC$2:$AC$97,"T") | H14: =(E14+F14)/96 | I14: =(D14+E14)/96 | J14: =(D14+G14)/96 | K14: =IF(AND(H14>=0.4,H14<=0.6,I14>=0.4,I14<=0.6,J14>=0.4,J14<=0.6,MIN(D14:G14)>=14.4),"是","否")
A15: 96 组 | B15: i7 | C15: 4 | D15: =COUNTIF('96对'!$AD$2:$AD$97,"A") | E15: =COUNTIF('96对'!$AD$2:$AD$97,"C") | F15: =COUNTIF('96对'!$AD$2:$AD$97,"G") | G15: =COUNTIF('96对'!$AD$2:$AD$97,"T") | H15: =(E15+F15)/96 | I15: =(D15+E15)/96 | J15: =(D15+G15)/96 | K15: =IF(AND(H15>=0.4,H15<=0.6,I15>=0.4,I15<=0.6,J15>=0.4,J15<=0.6,MIN(D15:G15)>=14.4),"是","否")
A16: 96 组 | B16: i7 | C16: 5 | D16: =COUNTIF('96对'!$AE$2:$AE$97,"A") | E16: =COUNTIF('96对'!$AE$2:$AE$97,"C") | F16: =COUNTIF('96对'!$AE$2:$AE$97,"G") | G16: =COUNTIF('96对'!$AE$2:$AE$97,"T") | H16: =(E16+F16)/96 | I16: =(D16+E16)/96 | J16: =(D16+G16)/96 | K16: =IF(AND(H16>=0.4,H16<=0.6,I16>=0.4,I16<=0.6,J16>=0.4,J16<=0.6,MIN(D16:G16)>=14.4),"是","否")
A17: 96 组 | B17: i7 | C17: 6 | D17: =COUNTIF('96对'!$AF$2:$AF$97,"A") | E17: =COUNTIF('96对'!$AF$2:$AF$97,"C") | F17: =COUNTIF('96对'!$AF$2:$AF$97,"G") | G17: =COUNTIF('96对'!$AF$2:$AF$97,"T") | H17: =(E17+F17)/96 | I17: =(D17+E17)/96 | J17: =(D17+G17)/96 | K17: =IF(AND(H17>=0.4,H17<=0.6,I17>=0.4,I17<=0.6,J17>=0.4,J17<=0.6,MIN(D17:G17)>=14.4),"是","否")
A18: 96 组 | B18: i7 | C18: 7 | D18: =COUNTIF('96对'!$AG$2:$AG$97,"A") | E18: =COUNTIF('96对'!$AG$2:$AG$97,"C") | F18: =COUNTIF('96对'!$AG$2:$AG$97,"G") | G18: =COUNTIF('96对'!$AG$2:$AG$97,"T") | H18: =(E18+F18)/96 | I18: =(D18+E18)/96 | J18: =(D18+G18)/96 | K18: =IF(AND(H18>=0.4,H18<=0.6,I18>=0.4,I18<=0.6,J18>=0.4,J18<=0.6,MIN(D18:G18)>=14.4),"是","否")
A19: 96 组 | B19: i7 | C19: 8 | D19: =COUNTIF('96对'!$AH$2:$AH$97,"A") | E19: =COUNTIF('96对'!$AH$2:$AH$97,"C") | F19: =COUNTIF('96对'!$AH$2:$AH$97,"G") | G19: =COUNTIF('96对'!$AH$2:$AH$97,"T") | H19: =(E19+F19)/96 | I19: =(D19+E19)/96 | J19: =(D19+G19)/96 | K19: =IF(AND(H19>=0.4,H19<=0.6,I19>=0.4,I19<=0.6,J19>=0.4,J19<=0.6,MIN(D19:G19)>=14.4),"是","否")
A20: 96 组 | B20: i7 | C20: 9 | D20: =COUNTIF('96对'!$AI$2:$AI$97,"A") | E20: =COUNTIF('96对'!$AI$2:$AI$97,"C") | F20: =COUNTIF('96对'!$AI$2:$AI$97,"G") | G20: =COUNTIF('96对'!$AI$2:$AI$97,"T") | H20: =(E20+F20)/96 | I20: =(D20+E20)/96 | J20: =(D20+G20)/96 | K20: =IF(AND(H20>=0.4,H20<=0.6,I20>=0.4,I20<=0.6,J20>=0.4,J20<=0.6,MIN(D20:G20)>=14.4),"是","否")
A21: 96 组 | B21: i7 | C21: 10 | D21: =COUNTIF('96对'!$AJ$2:$AJ$97,"A") | E21: =COUNTIF('96对'!$AJ$2:$AJ$97,"C") | F21: =COUNTIF('96对'!$AJ$2:$AJ$97,"G") | G21: =COUNTIF('96对'!$AJ$2:$AJ$97,"T") | H21: =(E21+F21)/96 | I21: =(D21+E21)/96 | J21: =(D21+G21)/96 | K21: =IF(AND(H21>=0.4,H21<=0.6,I21>=0.4,I21<=0.6,J21>=0.4,J21<=0.6,MIN(D21:G21)>=14.4),"是","否")
A22: 核心 48 组 | B22: i5 | C22: 1 | D22: =COUNTIF('96对'!$Q$2:$Q$49,"A") | E22: =COUNTIF('96对'!$Q$2:$Q$49,"C") | F22: =COUNTIF('96对'!$Q$2:$Q$49,"G") | G22: =COUNTIF('96对'!$Q$2:$Q$49,"T") | H22: =(E22+F22)/48 | I22: =(D22+E22)/48 | J22: =(D22+G22)/48 | K22: =IF(AND(H22>=0.4,H22<=0.6,I22>=0.4,I22<=0.6,J22>=0.4,J22<=0.6,MIN(D22:G22)>=7.2),"是","否")
A23: 核心 48 组 | B23: i5 | C23: 2 | D23: =COUNTIF('96对'!$R$2:$R$49,"A") | E23: =COUNTIF('96对'!$R$2:$R$49,"C") | F23: =COUNTIF('96对'!$R$2:$R$49,"G") | G23: =COUNTIF('96对'!$R$2:$R$49,"T") | H23: =(E23+F23)/48 | I23: =(D23+E23)/48 | J23: =(D23+G23)/48 | K23: =IF(AND(H23>=0.4,H23<=0.6,I23>=0.4,I23<=0.6,J23>=0.4,J23<=0.6,MIN(D23:G23)>=7.2),"是","否")
A24: 核心 48 组 | B24: i5 | C24: 3 | D24: =COUNTIF('96对'!$S$2:$S$49,"A") | E24: =COUNTIF('96对'!$S$2:$S$49,"C") | F24: =COUNTIF('96对'!$S$2:$S$49,"G") | G24: =COUNTIF('96对'!$S$2:$S$49,"T") | H24: =(E24+F24)/48 | I24: =(D24+E24)/48 | J24: =(D24+G24)/48 | K24: =IF(AND(H24>=0.4,H24<=0.6,I24>=0.4,I24<=0.6,J24>=0.4,J24<=0.6,MIN(D24:G24)>=7.2),"是","否")
A25: 核心 48 组 | B25: i5 | C25: 4 | D25: =COUNTIF('96对'!$T$2:$T$49,"A") | E25: =COUNTIF('96对'!$T$2:$T$49,"C") | F25: =COUNTIF('96对'!$T$2:$T$49,"G") | G25: =COUNTIF('96对'!$T$2:$T$49,"T") | H25: =(E25+F25)/48 | I25: =(D25+E25)/48 | J25: =(D25+G25)/48 | K25: =IF(AND(H25>=0.4,H25<=0.6,I25>=0.4,I25<=0.6,J25>=0.4,J25<=0.6,MIN(D25:G25)>=7.2),"是","否")
A26: 核心 48 组 | B26: i5 | C26: 5 | D26: =COUNTIF('96对'!$U$2:$U$49,"A") | E26: =COUNTIF('96对'!$U$2:$U$49,"C") | F26: =COUNTIF('96对'!$U$2:$U$49,"G") | G26: =COUNTIF('96对'!$U$2:$U$49,"T") | H26: =(E26+F26)/48 | I26: =(D26+E26)/48 | J26: =(D26+G26)/48 | K26: =IF(AND(H26>=0.4,H26<=0.6,I26>=0.4,I26<=0.6,J26>=0.4,J26<=0.6,MIN(D26:G26)>=7.2),"是","否")
A27: 核心 48 组 | B27: i5 | C27: 6 | D27: =COUNTIF('96对'!$V$2:$V$49,"A") | E27: =COUNTIF('96对'!$V$2:$V$49,"C") | F27: =COUNTIF('96对'!$V$2:$V$49,"G") | G27: =COUNTIF('96对'!$V$2:$V$49,"T") | H27: =(E27+F27)/48 | I27: =(D27+E27)/48 | J27: =(D27+G27)/48 | K27: =IF(AND(H27>=0.4,H27<=0.6,I27>=0.4,I27<=0.6,J27>=0.4,J27<=0.6,MIN(D27:G27)>=7.2),"是","否")
A28: 核心 48 组 | B28: i5 | C28: 7 | D28: =COUNTIF('96对'!$W$2:$W$49,"A") | E28: =COUNTIF('96对'!$W$2:$W$49,"C") | F28: =COUNTIF('96对'!$W$2:$W$49,"G") | G28: =COUNTIF('96对'!$W$2:$W$49,"T") | H28: =(E28+F28)/48 | I28: =(D28+E28)/48 | J28: =(D28+G28)/48 | K28: =IF(AND(H28>=0.4,H28<=0.6,I28>=0.4,I28<=0.6,J28>=0.4,J28<=0.6,MIN(D28:G28)>=7.2),"是","否")
A29: 核心 48 组 | B29: i5 | C29: 8 | D29: =COUNTIF('96对'!$X$2:$X$49,"A") | E29: =COUNTIF('96对'!$X$2:$X$49,"C") | F29: =COUNTIF('96对'!$X$2:$X$49,"G") | G29: =COUNTIF('96对'!$X$2:$X$49,"T") | H29: =(E29+F29)/48 | I29: =(D29+E29)/48 | J29: =(D29+G29)/48 | K29: =IF(AND(H29>=0.4,H29<=0.6,I29>=0.4,I29<=0.6,J29>=0.4,J29<=0.6,MIN(D29:G29)>=7.2),"是","否")
A30: 核心 48 组 | B30: i5 | C30: 9 | D30: =COUNTIF('96对'!$Y$2:$Y$49,"A") | E30: =COUNTIF('96对'!$Y$2:$Y$49,"C") | F30: =COUNTIF('96对'!$Y$2:$Y$49,"G") | G30: =COUNTIF('96对'!$Y$2:$Y$49,"T") | H30: =(E30+F30)/48 | I30: =(D30+E30)/48 | J30: =(D30+G30)/48 | K30: =IF(AND(H30>=0.4,H30<=0.6,I30>=0.4,I30<=0.6,J30>=0.4,J30<=0.6,MIN(D30:G30)>=7.2),"是","否")
A31: 核心 48 组 | B31: i5 | C31: 10 | D31: =COUNTIF('96对'!$Z$2:$Z$49,"A") | E31: =COUNTIF('96对'!$Z$2:$Z$49,"C") | F31: =COUNTIF('96对'!$Z$2:$Z$49,"G") | G31: =COUNTIF('96对'!$Z$2:$Z$49,"T") | H31: =(E31+F31)/48 | I31: =(D31+E31)/48 | J31: =(D31+G31)/48 | K31: =IF(AND(H31>=0.4,H31<=0.6,I31>=0.4,I31<=0.6,J31>=0.4,J31<=0.6,MIN(D31:G31)>=7.2),"是","否")
A32: 核心 48 组 | B32: i7 | C32: 1 | D32: =COUNTIF('96对'!$AA$2:$AA$49,"A") | E32: =COUNTIF('96对'!$AA$2:$AA$49,"C") | F32: =COUNTIF('96对'!$AA$2:$AA$49,"G") | G32: =COUNTIF('96对'!$AA$2:$AA$49,"T") | H32: =(E32+F32)/48 | I32: =(D32+E32)/48 | J32: =(D32+G32)/48 | K32: =IF(AND(H32>=0.4,H32<=0.6,I32>=0.4,I32<=0.6,J32>=0.4,J32<=0.6,MIN(D32:G32)>=7.2),"是","否")
A33: 核心 48 组 | B33: i7 | C33: 2 | D33: =COUNTIF('96对'!$AB$2:$AB$49,"A") | E33: =COUNTIF('96对'!$AB$2:$AB$49,"C") | F33: =COUNTIF('96对'!$AB$2:$AB$49,"G") | G33: =COUNTIF('96对'!$AB$2:$AB$49,"T") | H33: =(E33+F33)/48 | I33: =(D33+E33)/48 | J33: =(D33+G33)/48 | K33: =IF(AND(H33>=0.4,H33<=0.6,I33>=0.4,I33<=0.6,J33>=0.4,J33<=0.6,MIN(D33:G33)>=7.2),"是","否")
A34: 核心 48 组 | B34: i7 | C34: 3 | D34: =COUNTIF('96对'!$AC$2:$AC$49,"A") | E34: =COUNTIF('96对'!$AC$2:$AC$49,"C") | F34: =COUNTIF('96对'!$AC$2:$AC$49,"G") | G34: =COUNTIF('96对'!$AC$2:$AC$49,"T") | H34: =(E34+F34)/48 | I34: =(D34+E34)/48 | J34: =(D34+G34)/48 | K34: =IF(AND(H34>=0.4,H34<=0.6,I34>=0.4,I34<=0.6,J34>=0.4,J34<=0.6,MIN(D34:G34)>=7.2),"是","否")
A35: 核心 48 组 | B35: i7 | C35: 4 | D35: =COUNTIF('96对'!$AD$2:$AD$49,"A") | E35: =COUNTIF('96对'!$AD$2:$AD$49,"C") | F35: =COUNTIF('96对'!$AD$2:$AD$49,"G") | G35: =COUNTIF('96对'!$AD$2:$AD$49,"T") | H35: =(E35+F35)/48 | I35: =(D35+E35)/48 | J35: =(D35+G35)/48 | K35: =IF(AND(H35>=0.4,H35<=0.6,I35>=0.4,I35<=0.6,J35>=0.4,J35<=0.6,MIN(D35:G35)>=7.2),"是","否")
A36: 核心 48 组 | B36: i7 | C36: 5 | D36: =COUNTIF('96对'!$AE$2:$AE$49,"A") | E36: =COUNTIF('96对'!$AE$2:$AE$49,"C") | F36: =COUNTIF('96对'!$AE$2:$AE$49,"G") | G36: =COUNTIF('96对'!$AE$2:$AE$49,"T") | H36: =(E36+F36)/48 | I36: =(D36+E36)/48 | J36: =(D36+G36)/48 | K36: =IF(AND(H36>=0.4,H36<=0.6,I36>=0.4,I36<=0.6,J36>=0.4,J36<=0.6,MIN(D36:G36)>=7.2),"是","否")
A37: 核心 48 组 | B37: i7 | C37: 6 | D37: =COUNTIF('96对'!$AF$2:$AF$49,"A") | E37: =COUNTIF('96对'!$AF$2:$AF$49,"C") | F37: =COUNTIF('96对'!$AF$2:$AF$49,"G") | G37: =COUNTIF('96对'!$AF$2:$AF$49,"T") | H37: =(E37+F37)/48 | I37: =(D37+E37)/48 | J37: =(D37+G37)/48 | K37: =IF(AND(H37>=0.4,H37<=0.6,I37>=0.4,I37<=0.6,J37>=0.4,J37<=0.6,MIN(D37:G37)>=7.2),"是","否")
A38: 核心 48 组 | B38: i7 | C38: 7 | D38: =COUNTIF('96对'!$AG$2:$AG$49,"A") | E38: =COUNTIF('96对'!$AG$2:$AG$49,"C") | F38: =COUNTIF('96对'!$AG$2:$AG$49,"G") | G38: =COUNTIF('96对'!$AG$2:$AG$49,"T") | H38: =(E38+F38)/48 | I38: =(D38+E38)/48 | J38: =(D38+G38)/48 | K38: =IF(AND(H38>=0.4,H38<=0.6,I38>=0.4,I38<=0.6,J38>=0.4,J38<=0.6,MIN(D38:G38)>=7.2),"是","否")
A39: 核心 48 组 | B39: i7 | C39: 8 | D39: =COUNTIF('96对'!$AH$2:$AH$49,"A") | E39: =COUNTIF('96对'!$AH$2:$AH$49,"C") | F39: =COUNTIF('96对'!$AH$2:$AH$49,"G") | G39: =COUNTIF('96对'!$AH$2:$AH$49,"T") | H39: =(E39+F39)/48 | I39: =(D39+E39)/48 | J39: =(D39+G39)/48 | K39: =IF(AND(H39>=0.4,H39<=0.6,I39>=0.4,I39<=0.6,J39>=0.4,J39<=0.6,MIN(D39:G39)>=7.2),"是","否")
A40: 核心 48 组 | B40: i7 | C40: 9 | D40: =COUNTIF('96对'!$AI$2:$AI$49,"A") | E40: =COUNTIF('96对'!$AI$2:$AI$49,"C") | F40: =COUNTIF('96对'!$AI$2:$AI$49,"G") | G40: =COUNTIF('96对'!$AI$2:$AI$49,"T") | H40: =(E40+F40)/48 | I40: =(D40+E40)/48 | J40: =(D40+G40)/48 | K40: =IF(AND(H40>=0.4,H40<=0.6,I40>=0.4,I40<=0.6,J40>=0.4,J40<=0.6,MIN(D40:G40)>=7.2),"是","否")
...
