Workbook

Sheet 说明
A1: Illumina UDP（Set A–D）48 组与 96 组内联索引推荐
A2: 来源：Illumina Adapter Sequences（文档 1000000002694 v22）的 UDP0001–0384，i5/i7 取 “Bases in Adapter” 列，i5 加在正向引物 5′端，同编号 i7 加在反向引物 5′端，没有接头。已排除 UDP0017（你们测试测序量显著降低）。Oligonucleotide sequences © 2025 Illumina, Inc. All rights reserved.
A3: 筛选与硬约束：① i5 之间、i7 之间、i5 与 i7 之间的 Levenshtein 编辑距离都 ≥4（实测最小值 4）；② 每个周期（第 1–10 位）GC 占比、A+C 占比、A+T 占比都在 40–60%，A/C/G/T 每种 ≥15%（i5、i7 各自满足）；③ 近回文索引已剔除，无同聚物 ≥3；④ 每个管（同编号 i5+i7 加到 33 条引物池）的二聚体分级为 A 或 B，没有 C 级。
A4: 分级（经验阈值，没有文献依据）：A = 管内全局二聚体 ΔG ≥ −7 且 3′端 ≥ −4.5（58 °C，primer3）；B = ≥ −8.5 且 ≥ −5.5；无尾巴基线为 −5.7 / −3.8。
A5: 结果：48 组 = 28 个 A + 20 个 B；96 组 = 40 个 A + 56 个 B，48 组是 96 组的子集（先做 48 再扩到 96 即可）。
A6: 为什么 48 组不能只含 A 级：A 级候选的 i5 第 10 位（紧邻引物）只有 A/T，这个周期 GC 为 0%，C/G 没有信号；i5 以 G/C 结尾的候选全是 B 级，满足 GC ≥40% 至少要 20 个，所以 20 个 B 是下限。
A7: 提醒：① 部分索引单个 GC 为 3 或 7（占 10 位的 30% 或 70%）：48 组 i5 17 个、i7 16 个，96 组 i5 29 个、i7 31 个，每个周期仍达标；② i5 与 rc(i7) 的最小编辑距离只有 2，ONT 反向读取时要靠引物序列判断方向；③ 二聚体、发夹按 33 条引物池 + 单个管内的 i5/i7 评估，没有真实接头；④ 脱靶：尾巴放在 5′端，不改变 3′端种子，人和猪基因组全长（含尾巴）≤3 错配的位点见 96 组表；⑤ 混合建库后样本间 UDP 互补：头尾配对最长互补 7 nt、60 °C 最差 ΔG −5.4，锅柄最差 −3.1，没有 10 nt 完全互补（原始 UDP0001–0096 有 16 对）。

Sheet 96组
A1: 序号 | B1: UDP | C1: 在48组 | D1: i5（正向引物尾巴） | E1: i7（反向引物尾巴） | F1: i5 GC | G1: i7 GC | H1: 分级 | I1: 管内全局二聚体最差 ΔG | J1: 3′端最差 ΔG | K1: 发夹最差 ΔG | L1: Olivar 总坏度 | M1: 人 全长≤3错配位点 | N1: 人 ≤4 | O1: 猪 全长≤3错配位点 | P1: 猪 ≤4 | Q1: i5 第1位 | R1: i5 第2位 | S1: i5 第3位 | T1: i5 第4位 | U1: i5 第5位 | V1: i5 第6位 | W1: i5 第7位 | X1: i5 第8位 | Y1: i5 第9位 | Z1: i5 第10位 | AA1: i7 第1位 | AB1: i7 第2位 | AC1: i7 第3位 | AD1: i7 第4位 | AE1: i7 第5位 | AF1: i7 第6位 | AG1: i7 第7位 | AH1: i7 第8位 | AI1: i7 第9位 | AJ1: i7 第10位
A2: 1 | B2: UDP0004 | C2: 是 | D2: TGCCTGGTGG | E2: CTTATGGAAT | F2: =LEN(SUBSTITUTE(SUBSTITUTE(D2,"A",""),"T","")) | G2: =LEN(SUBSTITUTE(SUBSTITUTE(E2,"A",""),"T","")) | H2: B | I2: -8.22 | J2: -3.93 | K2: -1.59 | L2: 167559 | M2: 0 | N2: 0 | O2: 0 | P2: 2 | Q2: =MID($D2,1,1) | R2: =MID($D2,2,1) | S2: =MID($D2,3,1) | T2: =MID($D2,4,1) | U2: =MID($D2,5,1) | V2: =MID($D2,6,1) | W2: =MID($D2,7,1) | X2: =MID($D2,8,1) | Y2: =MID($D2,9,1) | Z2: =MID($D2,10,1) | AA2: =MID($E2,1,1) | AB2: =MID($E2,2,1) | AC2: =MID($E2,3,1) | AD2: =MID($E2,4,1) | AE2: =MID($E2,5,1) | AF2: =MID($E2,6,1) | AG2: =MID($E2,7,1) | AH2: =MID($E2,8,1) | AI2: =MID($E2,9,1) | AJ2: =MID($E2,10,1)
A3: 2 | B3: UDP0013 | C3: 是 | D3: ATCACGAAGG | E3: TAATGGCAAG | F3: =LEN(SUBSTITUTE(SUBSTITUTE(D3,"A",""),"T","")) | G3: =LEN(SUBSTITUTE(SUBSTITUTE(E3,"A",""),"T","")) | H3: B | I3: -7.82 | J3: -3.99 | K3: -1.77 | L3: 84882 | M3: 0 | N3: 0 | O3: 0 | P3: 0 | Q3: =MID($D3,1,1) | R3: =MID($D3,2,1) | S3: =MID($D3,3,1) | T3: =MID($D3,4,1) | U3: =MID($D3,5,1) | V3: =MID($D3,6,1) | W3: =MID($D3,7,1) | X3: =MID($D3,8,1) | Y3: =MID($D3,9,1) | Z3: =MID($D3,10,1) | AA3: =MID($E3,1,1) | AB3: =MID($E3,2,1) | AC3: =MID($E3,3,1) | AD3: =MID($E3,4,1) | AE3: =MID($E3,5,1) | AF3: =MID($E3,6,1) | AG3: =MID($E3,7,1) | AH3: =MID($E3,8,1) | AI3: =MID($E3,9,1) | AJ3: =MID($E3,10,1)
A4: 3 | B4: UDP0025 | C4: 是 | D4: GGCGAGATGG | E4: TTCTATGGTT | F4: =LEN(SUBSTITUTE(SUBSTITUTE(D4,"A",""),"T","")) | G4: =LEN(SUBSTITUTE(SUBSTITUTE(E4,"A",""),"T","")) | H4: B | I4: -7.22 | J4: -4.53 | K4: -1.59 | L4: 107258 | M4: 0 | N4: 0 | O4: 0 | P4: 1 | Q4: =MID($D4,1,1) | R4: =MID($D4,2,1) | S4: =MID($D4,3,1) | T4: =MID($D4,4,1) | U4: =MID($D4,5,1) | V4: =MID($D4,6,1) | W4: =MID($D4,7,1) | X4: =MID($D4,8,1) | Y4: =MID($D4,9,1) | Z4: =MID($D4,10,1) | AA4: =MID($E4,1,1) | AB4: =MID($E4,2,1) | AC4: =MID($E4,3,1) | AD4: =MID($E4,4,1) | AE4: =MID($E4,5,1) | AF4: =MID($E4,6,1) | AG4: =MID($E4,7,1) | AH4: =MID($E4,8,1) | AI4: =MID($E4,9,1) | AJ4: =MID($E4,10,1)
A5: 4 | B5: UDP0027 | C5: 是 | D5: TCAATCCATT | E5: TGGATGCTTA | F5: =LEN(SUBSTITUTE(SUBSTITUTE(D5,"A",""),"T","")) | G5: =LEN(SUBSTITUTE(SUBSTITUTE(E5,"A",""),"T","")) | H5: A | I5: -6.1 | J5: -3.79 | K5: -2.61 | L5: 48463 | M5: 0 | N5: 5 | O5: 0 | P5: 1 | Q5: =MID($D5,1,1) | R5: =MID($D5,2,1) | S5: =MID($D5,3,1) | T5: =MID($D5,4,1) | U5: =MID($D5,5,1) | V5: =MID($D5,6,1) | W5: =MID($D5,7,1) | X5: =MID($D5,8,1) | Y5: =MID($D5,9,1) | Z5: =MID($D5,10,1) | AA5: =MID($E5,1,1) | AB5: =MID($E5,2,1) | AC5: =MID($E5,3,1) | AD5: =MID($E5,4,1) | AE5: =MID($E5,5,1) | AF5: =MID($E5,6,1) | AG5: =MID($E5,7,1) | AH5: =MID($E5,8,1) | AI5: =MID($E5,9,1) | AJ5: =MID($E5,10,1)
A6: 5 | B6: UDP0033 | C6: 是 | D6: GTCGATTACA | E6: CGTATAATCA | F6: =LEN(SUBSTITUTE(SUBSTITUTE(D6,"A",""),"T","")) | G6: =LEN(SUBSTITUTE(SUBSTITUTE(E6,"A",""),"T","")) | H6: A | I6: -6.44 | J6: -3.83 | K6: -2.61 | L6: 43551 | M6: 0 | N6: 0 | O6: 0 | P6: 0 | Q6: =MID($D6,1,1) | R6: =MID($D6,2,1) | S6: =MID($D6,3,1) | T6: =MID($D6,4,1) | U6: =MID($D6,5,1) | V6: =MID($D6,6,1) | W6: =MID($D6,7,1) | X6: =MID($D6,8,1) | Y6: =MID($D6,9,1) | Z6: =MID($D6,10,1) | AA6: =MID($E6,1,1) | AB6: =MID($E6,2,1) | AC6: =MID($E6,3,1) | AD6: =MID($E6,4,1) | AE6: =MID($E6,5,1) | AF6: =MID($E6,6,1) | AG6: =MID($E6,7,1) | AH6: =MID($E6,8,1) | AI6: =MID($E6,9,1) | AJ6: =MID($E6,10,1)
A7: 6 | B7: UDP0057 | C7: 是 | D7: CGTCGACTGG | E7: TTAGGATAGA | F7: =LEN(SUBSTITUTE(SUBSTITUTE(D7,"A",""),"T","")) | G7: =LEN(SUBSTITUTE(SUBSTITUTE(E7,"A",""),"T","")) | H7: B | I7: -7.93 | J7: -4.39 | K7: -2.61 | L7: 181301 | M7: 0 | N7: 1 | O7: 0 | P7: 0 | Q7: =MID($D7,1,1) | R7: =MID($D7,2,1) | S7: =MID($D7,3,1) | T7: =MID($D7,4,1) | U7: =MID($D7,5,1) | V7: =MID($D7,6,1) | W7: =MID($D7,7,1) | X7: =MID($D7,8,1) | Y7: =MID($D7,9,1) | Z7: =MID($D7,10,1) | AA7: =MID($E7,1,1) | AB7: =MID($E7,2,1) | AC7: =MID($E7,3,1) | AD7: =MID($E7,4,1) | AE7: =MID($E7,5,1) | AF7: =MID($E7,6,1) | AG7: =MID($E7,7,1) | AH7: =MID($E7,8,1) | AI7: =MID($E7,9,1) | AJ7: =MID($E7,10,1)
A8: 7 | B8: UDP0059 | C8: 是 | D8: ATAGACCGTT | E8: GGACCAACAG | F8: =LEN(SUBSTITUTE(SUBSTITUTE(D8,"A",""),"T","")) | G8: =LEN(SUBSTITUTE(SUBSTITUTE(E8,"A",""),"T","")) | H8: A | I8: -6.23 | J8: -4.41 | K8: -1.77 | L8: 36992 | M8: 0 | N8: 0 | O8: 0 | P8: 0 | Q8: =MID($D8,1,1) | R8: =MID($D8,2,1) | S8: =MID($D8,3,1) | T8: =MID($D8,4,1) | U8: =MID($D8,5,1) | V8: =MID($D8,6,1) | W8: =MID($D8,7,1) | X8: =MID($D8,8,1) | Y8: =MID($D8,9,1) | Z8: =MID($D8,10,1) | AA8: =MID($E8,1,1) | AB8: =MID($E8,2,1) | AC8: =MID($E8,3,1) | AD8: =MID($E8,4,1) | AE8: =MID($E8,5,1) | AF8: =MID($E8,6,1) | AG8: =MID($E8,7,1) | AH8: =MID($E8,8,1) | AI8: =MID($E8,9,1) | AJ8: =MID($E8,10,1)
A9: 8 | B9: UDP0060 | C9: 是 | D9: ACAGTTCCAG | E9: TTCCAGGTAA | F9: =LEN(SUBSTITUTE(SUBSTITUTE(D9,"A",""),"T","")) | G9: =LEN(SUBSTITUTE(SUBSTITUTE(E9,"A",""),"T","")) | H9: B | I9: -8.21 | J9: -5.43 | K9: -2.61 | L9: 154331 | M9: 0 | N9: 2 | O9: 0 | P9: 3 | Q9: =MID($D9,1,1) | R9: =MID($D9,2,1) | S9: =MID($D9,3,1) | T9: =MID($D9,4,1) | U9: =MID($D9,5,1) | V9: =MID($D9,6,1) | W9: =MID($D9,7,1) | X9: =MID($D9,8,1) | Y9: =MID($D9,9,1) | Z9: =MID($D9,10,1) | AA9: =MID($E9,1,1) | AB9: =MID($E9,2,1) | AC9: =MID($E9,3,1) | AD9: =MID($E9,4,1) | AE9: =MID($E9,5,1) | AF9: =MID($E9,6,1) | AG9: =MID($E9,7,1) | AH9: =MID($E9,8,1) | AI9: =MID($E9,9,1) | AJ9: =MID($E9,10,1)
A10: 9 | B10: UDP0080 | C10: 是 | D10: CAAGCATCCG | E10: CTGGCTTGCC | F10: =LEN(SUBSTITUTE(SUBSTITUTE(D10,"A",""),"T","")) | G10: =LEN(SUBSTITUTE(SUBSTITUTE(E10,"A",""),"T","")) | H10: B | I10: -8.45 | J10: -4.43 | K10: -1.62 | L10: 122661 | M10: 0 | N10: 1 | O10: 0 | P10: 0 | Q10: =MID($D10,1,1) | R10: =MID($D10,2,1) | S10: =MID($D10,3,1) | T10: =MID($D10,4,1) | U10: =MID($D10,5,1) | V10: =MID($D10,6,1) | W10: =MID($D10,7,1) | X10: =MID($D10,8,1) | Y10: =MID($D10,9,1) | Z10: =MID($D10,10,1) | AA10: =MID($E10,1,1) | AB10: =MID($E10,2,1) | AC10: =MID($E10,3,1) | AD10: =MID($E10,4,1) | AE10: =MID($E10,5,1) | AF10: =MID($E10,6,1) | AG10: =MID($E10,7,1) | AH10: =MID($E10,8,1) | AI10: =MID($E10,9,1) | AJ10: =MID($E10,10,1)
A11: 10 | B11: UDP0089 | C11: 是 | D11: CGTGTATCTT | E11: GCTTACGGAC | F11: =LEN(SUBSTITUTE(SUBSTITUTE(D11,"A",""),"T","")) | G11: =LEN(SUBSTITUTE(SUBSTITUTE(E11,"A",""),"T","")) | H11: A | I11: -5.74 | J11: -3.79 | K11: -1.62 | L11: 47574 | M11: 0 | N11: 0 | O11: 0 | P11: 0 | Q11: =MID($D11,1,1) | R11: =MID($D11,2,1) | S11: =MID($D11,3,1) | T11: =MID($D11,4,1) | U11: =MID($D11,5,1) | V11: =MID($D11,6,1) | W11: =MID($D11,7,1) | X11: =MID($D11,8,1) | Y11: =MID($D11,9,1) | Z11: =MID($D11,10,1) | AA11: =MID($E11,1,1) | AB11: =MID($E11,2,1) | AC11: =MID($E11,3,1) | AD11: =MID($E11,4,1) | AE11: =MID($E11,5,1) | AF11: =MID($E11,6,1) | AG11: =MID($E11,7,1) | AH11: =MID($E11,8,1) | AI11: =MID($E11,9,1) | AJ11: =MID($E11,10,1)
A12: 11 | B12: UDP0092 | C12: 是 | D12: ACATACTTCC | E12: ATACCAACGC | F12: =LEN(SUBSTITUTE(SUBSTITUTE(D12,"A",""),"T","")) | G12: =LEN(SUBSTITUTE(SUBSTITUTE(E12,"A",""),"T","")) | H12: B | I12: -7.55 | J12: -4.54 | K12: -1.98 | L12: 146091 | M12: 0 | N12: 0 | O12: 0 | P12: 0 | Q12: =MID($D12,1,1) | R12: =MID($D12,2,1) | S12: =MID($D12,3,1) | T12: =MID($D12,4,1) | U12: =MID($D12,5,1) | V12: =MID($D12,6,1) | W12: =MID($D12,7,1) | X12: =MID($D12,8,1) | Y12: =MID($D12,9,1) | Z12: =MID($D12,10,1) | AA12: =MID($E12,1,1) | AB12: =MID($E12,2,1) | AC12: =MID($E12,3,1) | AD12: =MID($E12,4,1) | AE12: =MID($E12,5,1) | AF12: =MID($E12,6,1) | AG12: =MID($E12,7,1) | AH12: =MID($E12,8,1) | AI12: =MID($E12,9,1) | AJ12: =MID($E12,10,1)
A13: 12 | B13: UDP0109 | C13: 是 | D13: GTAGCCATCA | E13: TAATTCTACC | F13: =LEN(SUBSTITUTE(SUBSTITUTE(D13,"A",""),"T","")) | G13: =LEN(SUBSTITUTE(SUBSTITUTE(E13,"A",""),"T","")) | H13: A | I13: -6.03 | J13: -3.83 | K13: -1.62 | L13: 92341 | M13: 0 | N13: 1 | O13: 0 | P13: 0 | Q13: =MID($D13,1,1) | R13: =MID($D13,2,1) | S13: =MID($D13,3,1) | T13: =MID($D13,4,1) | U13: =MID($D13,5,1) | V13: =MID($D13,6,1) | W13: =MID($D13,7,1) | X13: =MID($D13,8,1) | Y13: =MID($D13,9,1) | Z13: =MID($D13,10,1) | AA13: =MID($E13,1,1) | AB13: =MID($E13,2,1) | AC13: =MID($E13,3,1) | AD13: =MID($E13,4,1) | AE13: =MID($E13,5,1) | AF13: =MID($E13,6,1) | AG13: =MID($E13,7,1) | AH13: =MID($E13,8,1) | AI13: =MID($E13,9,1) | AJ13: =MID($E13,10,1)
... A49: 48 | B49: UDP0384 | C49: 是 | D49: GGTGGAATAC | E49: CTTAACCACT | F49: =LEN(SUBSTITUTE(SUBSTITUTE(D49,"A",""),"T","")) | G49: =LEN(SUBSTITUTE(SUBSTITUTE(E49,"A",""),"T","")) | H49: B | I49: -6.73 | J49: -4.95 | K49: -1.59 | L49: 58743 | M49: 0 | N49: 0 | O49: 0 | P49: 0 | Q49: =MID($D49,1,1) | R49: =MID($D49,2,1) | S49: =MID($D49,3,1) | T49: =MID($D49,4,1) | U49: =MID($D49,5,1) | V49: =MID($D49,6,1) | W49: =MID($D49,7,1) | X49: =MID($D49,8,1) | Y49: =MID($D49,9,1) | Z49: =MID($D49,10,1) | AA49: =MID($E49,1,1) | AB49: =MID($E49,2,1) | AC49: =MID($E49,3,1) | AD49: =MID($E49,4,1) | AE49: =MID($E49,5,1) | AF49: =MID($E49,6,1) | AG49: =MID($E49,7,1) | AH49: =MID($E49,8,1) | AI49: =MID($E49,9,1) | AJ49: =MID($E49,10,1)
A50: 49 | B50: UDP0006 | D50: GTCCACTTGT | E50: GCGCGATGTT | F50: =LEN(SUBSTITUTE(SUBSTITUTE(D50,"A",""),"T","")) | G50: =LEN(SUBSTITUTE(SUBSTITUTE(E50,"A",""),"T","")) | H50: B | I50: -7.91 | J50: -3.79 | K50: -1.91 | L50: 50850 | M50: 0 | N50: 1 | O50: 0 | P50: 0 | Q50: =MID($D50,1,1) | R50: =MID($D50,2,1) | S50: =MID($D50,3,1) | T50: =MID($D50,4,1) | U50: =MID($D50,5,1) | V50: =MID($D50,6,1) | W50: =MID($D50,7,1) | X50: =MID($D50,8,1) | Y50: =MID($D50,9,1) | Z50: =MID($D50,10,1) | AA50: =MID($E50,1,1) | AB50: =MID($E50,2,1) | AC50: =MID($E50,3,1) | AD50: =MID($E50,4,1) | AE50: =MID($E50,5,1) | AF50: =MID($E50,6,1) | AG50: =MID($E50,7,1) | AH50: =MID($E50,8,1) | AI50: =MID($E50,9,1) | AJ50: =MID($E50,10,1)
A51: 50 | B51: UDP0014 | D51: CGGCTCTACT | E51: GTGCCGCTTC | F51: =LEN(SUBSTITUTE(SUBSTITUTE(D51,"A",""),"T","")) | G51: =LEN(SUBSTITUTE(SUBSTITUTE(E51,"A",""),"T","")) | H51: B | I51: -6.27 | J51: -4.96 | K51: -2.05 | L51: 51311 | M51: 0 | N51: 0 | O51: 0 | P51: 0 | Q51: =MID($D51,1,1) | R51: =MID($D51,2,1) | S51: =MID($D51,3,1) | T51: =MID($D51,4,1) | U51: =MID($D51,5,1) | V51: =MID($D51,6,1) | W51: =MID($D51,7,1) | X51: =MID($D51,8,1) | Y51: =MID($D51,9,1) | Z51: =MID($D51,10,1) | AA51: =MID($E51,1,1) | AB51: =MID($E51,2,1) | AC51: =MID($E51,3,1) | AD51: =MID($E51,4,1) | AE51: =MID($E51,5,1) | AF51: =MID($E51,6,1) | AG51: =MID($E51,7,1) | AH51: =MID($E51,8,1) | AI51: =MID($E51,9,1) | AJ51: =MID($E51,10,1)
A52: 51 | B52: UDP0019 | D52: GGTTGCCTCT | E52: CTAATGATGG | F52: =LEN(SUBSTITUTE(SUBSTITUTE(D52,"A",""),"T","")) | G52: =LEN(SUBSTITUTE(SUBSTITUTE(E52,"A",""),"T","")) | H52: B | I52: -5.93 | J52: -4.68 | K52: -2.3 | L52: 47027 | M52: 0 | N52: 0 | O52: 0 | P52: 1 | Q52: =MID($D52,1,1) | R52: =MID($D52,2,1) | S52: =MID($D52,3,1) | T52: =MID($D52,4,1) | U52: =MID($D52,5,1) | V52: =MID($D52,6,1) | W52: =MID($D52,7,1) | X52: =MID($D52,8,1) | Y52: =MID($D52,9,1) | Z52: =MID($D52,10,1) | AA52: =MID($E52,1,1) | AB52: =MID($E52,2,1) | AC52: =MID($E52,3,1) | AD52: =MID($E52,4,1) | AE52: =MID($E52,5,1) | AF52: =MID($E52,6,1) | AG52: =MID($E52,7,1) | AH52: =MID($E52,8,1) | AI52: =MID($E52,9,1) | AJ52: =MID($E52,10,1)
A53: 52 | B53: UDP0020 | D53: CGCACATGGC | E53: TCGGCCTATC | F53: =LEN(SUBSTITUTE(SUBSTITUTE(D53,"A",""),"T","")) | G53: =LEN(SUBSTITUTE(SUBSTITUTE(E53,"A",""),"T","")) | H53: B | I53: -8.03 | J53: -4.78 | K53: -1.62 | L53: 71056 | M53: 0 | N53: 0 | O53: 0 | P53: 0 | Q53: =MID($D53,1,1) | R53: =MID($D53,2,1) | S53: =MID($D53,3,1) | T53: =MID($D53,4,1) | U53: =MID($D53,5,1) | V53: =MID($D53,6,1) | W53: =MID($D53,7,1) | X53: =MID($D53,8,1) | Y53: =MID($D53,9,1) | Z53: =MID($D53,10,1) | AA53: =MID($E53,1,1) | AB53: =MID($E53,2,1) | AC53: =MID($E53,3,1) | AD53: =MID($E53,4,1) | AE53: =MID($E53,5,1) | AF53: =MID($E53,6,1) | AG53: =MID($E53,7,1) | AH53: =MID($E53,8,1) | AI53: =MID($E53,9,1) | AJ53: =MID($E53,10,1)
A54: 53 | B54: UDP0022 | D54: CTGTGTTAGG | E54: GAGCGCAATA | F54: =LEN(SUBSTITUTE(SUBSTITUTE(D54,"A",""),"T","")) | G54: =LEN(SUBSTITUTE(SUBSTITUTE(E54,"A",""),"T","")) | H54: B | I54: -7.9 | J54: -5.04 | K54: -2.61 | L54: 98234 | M54: 0 | N54: 0 | O54: 0 | P54: 0 | Q54: =MID($D54,1,1) | R54: =MID($D54,2,1) | S54: =MID($D54,3,1) | T54: =MID($D54,4,1) | U54: =MID($D54,5,1) | V54: =MID($D54,6,1) | W54: =MID($D54,7,1) | X54: =MID($D54,8,1) | Y54: =MID($D54,9,1) | Z54: =MID($D54,10,1) | AA54: =MID($E54,1,1) | AB54: =MID($E54,2,1) | AC54: =MID($E54,3,1) | AD54: =MID($E54,4,1) | AE54: =MID($E54,5,1) | AF54: =MID($E54,6,1) | AG54: =MID($E54,7,1) | AH54: =MID($E54,8,1) | AI54: =MID($E54,9,1) | AJ54: =MID($E54,10,1)
A55: 54 | B55: UDP0024 | D55: CTAACTGTAA | E55: GTATGTAGAA | F55: =LEN(SUBSTITUTE(SUBSTITUTE(D55,"A",""),"T","")) | G55: =LEN(SUBSTITUTE(SUBSTITUTE(E55,"A",""),"T","")) | H55: A | I55: -6.68 | J55: -3.87 | K55: -2.61 | L55: 45471 | M55: 0 | N55: 0 | O55: 0 | P55: 0 | Q55: =MID($D55,1,1) | R55: =MID($D55,2,1) | S55: =MID($D55,3,1) | T55: =MID($D55,4,1) | U55: =MID($D55,5,1) | V55: =MID($D55,6,1) | W55: =MID($D55,7,1) | X55: =MID($D55,8,1) | Y55: =MID($D55,9,1) | Z55: =MID($D55,10,1) | AA55: =MID($E55,1,1) | AB55: =MID($E55,2,1) | AC55: =MID($E55,3,1) | AD55: =MID($E55,4,1) | AE55: =MID($E55,5,1) | AF55: =MID($E55,6,1) | AG55: =MID($E55,7,1) | AH55: =MID($E55,8,1) | AI55: =MID($E55,9,1) | AJ55: =MID($E55,10,1)
A56: 55 | B56: UDP0051 | D56: ACTGTTGTGA | E56: GACAGACAGG | F56: =LEN(SUBSTITUTE(SUBSTITUTE(D56,"A",""),"T","")) | G56: =LEN(SUBSTITUTE(SUBSTITUTE(E56,"A",""),"T","")) | H56: B | I56: -7.07 | J56: -4.74 | K56: -2.35 | L56: 41652 | M56: 0 | N56: 0 | O56: 0 | P56: 5 | Q56: =MID($D56,1,1) | R56: =MID($D56,2,1) | S56: =MID($D56,3,1) | T56: =MID($D56,4,1) | U56: =MID($D56,5,1) | V56: =MID($D56,6,1) | W56: =MID($D56,7,1) | X56: =MID($D56,8,1) | Y56: =MID($D56,9,1) | Z56: =MID($D56,10,1) | AA56: =MID($E56,1,1) | AB56: =MID($E56,2,1) | AC56: =MID($E56,3,1) | AD56: =MID($E56,4,1) | AE56: =MID($E56,5,1) | AF56: =MID($E56,6,1) | AG56: =MID($E56,7,1) | AH56: =MID($E56,8,1) | AI56: =MID($E56,9,1) | AJ56: =MID($E56,10,1)
A57: 56 | B57: UDP0086 | D57: ACGTCAATAC | E57: GGAATTCCAA | F57: =LEN(SUBSTITUTE(SUBSTITUTE(D57,"A",""),"T","")) | G57: =LEN(SUBSTITUTE(SUBSTITUTE(E57,"A",""),"T","")) | H57: B | I57: -6.84 | J57: -4.95 | K57: -2.61 | L57: 318589 | M57: 1 | N57: 1 | O57: 0 | P57: 1 | Q57: =MID($D57,1,1) | R57: =MID($D57,2,1) | S57: =MID($D57,3,1) | T57: =MID($D57,4,1) | U57: =MID($D57,5,1) | V57: =MID($D57,6,1) | W57: =MID($D57,7,1) | X57: =MID($D57,8,1) | Y57: =MID($D57,9,1) | Z57: =MID($D57,10,1) | AA57: =MID($E57,1,1) | AB57: =MID($E57,2,1) | AC57: =MID($E57,3,1) | AD57: =MID($E57,4,1) | AE57: =MID($E57,5,1) | AF57: =MID($E57,6,1) | AG57: =MID($E57,7,1) | AH57: =MID($E57,8,1) | AI57: =MID($E57,9,1) | AJ57: =MID($E57,10,1)
A58: 57 | B58: UDP0108 | D58: ATGTCGTGGT | E58: CATGAGTACT | F58: =LEN(SUBSTITUTE(SUBSTITUTE(D58,"A",""),"T","")) | G58: =LEN(SUBSTITUTE(SUBSTITUTE(E58,"A",""),"T","")) | H58: A | I58: -6.8 | J58: -3.79 | K58: -1.59 | L58: 82153 | M58: 0 | N58: 0 | O58: 0 | P58: 1 | Q58: =MID($D58,1,1) | R58: =MID($D58,2,1) | S58: =MID($D58,3,1) | T58: =MID($D58,4,1) | U58: =MID($D58,5,1) | V58: =MID($D58,6,1) | W58: =MID($D58,7,1) | X58: =MID($D58,8,1) | Y58: =MID($D58,9,1) | Z58: =MID($D58,10,1) | AA58: =MID($E58,1,1) | AB58: =MID($E58,2,1) | AC58: =MID($E58,3,1) | AD58: =MID($E58,4,1) | AE58: =MID($E58,5,1) | AF58: =MID($E58,6,1) | AG58: =MID($E58,7,1) | AH58: =MID($E58,8,1) | AI58: =MID($E58,9,1) | AJ58: =MID($E58,10,1)
A59: 58 | B59: UDP0113 | D59: ACCGGCTCAG | E59: CTTGTAATTC | F59: =LEN(SUBSTITUTE(SUBSTITUTE(D59,"A",""),"T","")) | G59: =LEN(SUBSTITUTE(SUBSTITUTE(E59,"A",""),"T","")) | H59: B | I59: -7.8 | J59: -4.02 | K59: -1.62 | L59: 139226 | M59: 0 | N59: 0 | O59: 0 | P59: 0 | Q59: =MID($D59,1,1) | R59: =MID($D59,2,1) | S59: =MID($D59,3,1) | T59: =MID($D59,4,1) | U59: =MID($D59,5,1) | V59: =MID($D59,6,1) | W59: =MID($D59,7,1) | X59: =MID($D59,8,1) | Y59: =MID($D59,9,1) | Z59: =MID($D59,10,1) | AA59: =MID($E59,1,1) | AB59: =MID($E59,2,1) | AC59: =MID($E59,3,1) | AD59: =MID($E59,4,1) | AE59: =MID($E59,5,1) | AF59: =MID($E59,6,1) | AG59: =MID($E59,7,1) | AH59: =MID($E59,8,1) | AI59: =MID($E59,9,1) | AJ59: =MID($E59,10,1)
A60: 59 | B60: UDP0114 | D60: GTTAATCTGA | E60: TCCAATTCTA | F60: =LEN(SUBSTITUTE(SUBSTITUTE(D60,"A",""),"T","")) | G60: =LEN(SUBSTITUTE(SUBSTITUTE(E60,"A",""),"T","")) | H60: A | I60: -6.44 | J60: -3.83 | K60: -2.61 | L60: 63369 | M60: 0 | N60: 4 | O60: 0 | P60: 1 | Q60: =MID($D60,1,1) | R60: =MID($D60,2,1) | S60: =MID($D60,3,1) | T60: =MID($D60,4,1) | U60: =MID($D60,5,1) | V60: =MID($D60,6,1) | W60: =MID($D60,7,1) | X60: =MID($D60,8,1) | Y60: =MID($D60,9,1) | Z60: =MID($D60,10,1) | AA60: =MID($E60,1,1) | AB60: =MID($E60,2,1) | AC60: =MID($E60,3,1) | AD60: =MID($E60,4,1) | AE60: =MID($E60,5,1) | AF60: =MID($E60,6,1) | AG60: =MID($E60,7,1) | AH60: =MID($E60,8,1) | AI60: =MID($E60,9,1) | AJ60: =MID($E60,10,1)
A61: 60 | B61: UDP0118 | D61: TAACCGCCGA | E61: GAACAAGTAT | F61: =LEN(SUBSTITUTE(SUBSTITUTE(D61,"A",""),"T","")) | G61: =LEN(SUBSTITUTE(SUBSTITUTE(E61,"A",""),"T","")) | H61: B | I61: -7.92 | J61: -3.78 | K61: -1.59 | L61: 71445 | M61: 0 | N61: 0 | O61: 0 | P61: 0 | Q61: =MID($D61,1,1) | R61: =MID($D61,2,1) | S61: =MID($D61,3,1) | T61: =MID($D61,4,1) | U61: =MID($D61,5,1) | V61: =MID($D61,6,1) | W61: =MID($D61,7,1) | X61: =MID($D61,8,1) | Y61: =MID($D61,9,1) | Z61: =MID($D61,10,1) | AA61: =MID($E61,1,1) | AB61: =MID($E61,2,1) | AC61: =MID($E61,3,1) | AD61: =MID($E61,4,1) | AE61: =MID($E61,5,1) | AF61: =MID($E61,6,1) | AG61: =MID($E61,7,1) | AH61: =MID($E61,8,1) | AI61: =MID($E61,9,1) | AJ61: =MID($E61,10,1)
... A97: 96 | B97: UDP0380 | D97: TCCGATAGAG | E97: TCCATAATCC | F97: =LEN(SUBSTITUTE(SUBSTITUTE(D97,"A",""),"T","")) | G97: =LEN(SUBSTITUTE(SUBSTITUTE(E97,"A",""),"T","")) | H97: B | I97: -7.32 | J97: -4.02 | K97: -1.62 | L97: 176213 | M97: 0 | N97: 0 | O97: 0 | P97: 1 | Q97: =MID($D97,1,1) | R97: =MID($D97,2,1) | S97: =MID($D97,3,1) | T97: =MID($D97,4,1) | U97: =MID($D97,5,1) | V97: =MID($D97,6,1) | W97: =MID($D97,7,1) | X97: =MID($D97,8,1) | Y97: =MID($D97,9,1) | Z97: =MID($D97,10,1) | AA97: =MID($E97,1,1) | AB97: =MID($E97,2,1) | AC97: =MID($E97,3,1) | AD97: =MID($E97,4,1) | AE97: =MID($E97,5,1) | AF97: =MID($E97,6,1) | AG97: =MID($E97,7,1) | AH97: =MID($E97,8,1) | AI97: =MID($E97,9,1) | AJ97: =MID($E97,10,1)

Sheet 每周期统计
A1: 集合 | B1: 序列 | C1: 周期 | D1: A | E1: C | F1: G | G1: T | H1: GC% | I1: A+C% | J1: A+T% | K1: 是否达标
A2: 48 组 | B2: i5 | C2: 1 | D2: =COUNTIF('96组'!$Q$2:$Q$49,"A") | E2: =COUNTIF('96组'!$Q$2:$Q$49,"C") | F2: =COUNTIF('96组'!$Q$2:$Q$49,"G") | G2: =COUNTIF('96组'!$Q$2:$Q$49,"T") | H2: =(E2+F2)/48 | I2: =(D2+E2)/48 | J2: =(D2+G2)/48 | K2: =IF(AND(H2>=0.4,H2<=0.6,I2>=0.4,I2<=0.6,J2>=0.4,J2<=0.6,MIN(D2:G2)>=7.2),"是","否")
A3: 48 组 | B3: i5 | C3: 2 | D3: =COUNTIF('96组'!$R$2:$R$49,"A") | E3: =COUNTIF('96组'!$R$2:$R$49,"C") | F3: =COUNTIF('96组'!$R$2:$R$49,"G") | G3: =COUNTIF('96组'!$R$2:$R$49,"T") | H3: =(E3+F3)/48 | I3: =(D3+E3)/48 | J3: =(D3+G3)/48 | K3: =IF(AND(H3>=0.4,H3<=0.6,I3>=0.4,I3<=0.6,J3>=0.4,J3<=0.6,MIN(D3:G3)>=7.2),"是","否")
A4: 48 组 | B4: i5 | C4: 3 | D4: =COUNTIF('96组'!$S$2:$S$49,"A") | E4: =COUNTIF('96组'!$S$2:$S$49,"C") | F4: =COUNTIF('96组'!$S$2:$S$49,"G") | G4: =COUNTIF('96组'!$S$2:$S$49,"T") | H4: =(E4+F4)/48 | I4: =(D4+E4)/48 | J4: =(D4+G4)/48 | K4: =IF(AND(H4>=0.4,H4<=0.6,I4>=0.4,I4<=0.6,J4>=0.4,J4<=0.6,MIN(D4:G4)>=7.2),"是","否")
A5: 48 组 | B5: i5 | C5: 4 | D5: =COUNTIF('96组'!$T$2:$T$49,"A") | E5: =COUNTIF('96组'!$T$2:$T$49,"C") | F5: =COUNTIF('96组'!$T$2:$T$49,"G") | G5: =COUNTIF('96组'!$T$2:$T$49,"T") | H5: =(E5+F5)/48 | I5: =(D5+E5)/48 | J5: =(D5+G5)/48 | K5: =IF(AND(H5>=0.4,H5<=0.6,I5>=0.4,I5<=0.6,J5>=0.4,J5<=0.6,MIN(D5:G5)>=7.2),"是","否")
A6: 48 组 | B6: i5 | C6: 5 | D6: =COUNTIF('96组'!$U$2:$U$49,"A") | E6: =COUNTIF('96组'!$U$2:$U$49,"C") | F6: =COUNTIF('96组'!$U$2:$U$49,"G") | G6: =COUNTIF('96组'!$U$2:$U$49,"T") | H6: =(E6+F6)/48 | I6: =(D6+E6)/48 | J6: =(D6+G6)/48 | K6: =IF(AND(H6>=0.4,H6<=0.6,I6>=0.4,I6<=0.6,J6>=0.4,J6<=0.6,MIN(D6:G6)>=7.2),"是","否")
A7: 48 组 | B7: i5 | C7: 6 | D7: =COUNTIF('96组'!$V$2:$V$49,"A") | E7: =COUNTIF('96组'!$V$2:$V$49,"C") | F7: =COUNTIF('96组'!$V$2:$V$49,"G") | G7: =COUNTIF('96组'!$V$2:$V$49,"T") | H7: =(E7+F7)/48 | I7: =(D7+E7)/48 | J7: =(D7+G7)/48 | K7: =IF(AND(H7>=0.4,H7<=0.6,I7>=0.4,I7<=0.6,J7>=0.4,J7<=0.6,MIN(D7:G7)>=7.2),"是","否")
A8: 48 组 | B8: i5 | C8: 7 | D8: =COUNTIF('96组'!$W$2:$W$49,"A") | E8: =COUNTIF('96组'!$W$2:$W$49,"C") | F8: =COUNTIF('96组'!$W$2:$W$49,"G") | G8: =COUNTIF('96组'!$W$2:$W$49,"T") | H8: =(E8+F8)/48 | I8: =(D8+E8)/48 | J8: =(D8+G8)/48 | K8: =IF(AND(H8>=0.4,H8<=0.6,I8>=0.4,I8<=0.6,J8>=0.4,J8<=0.6,MIN(D8:G8)>=7.2),"是","否")
A9: 48 组 | B9: i5 | C9: 8 | D9: =COUNTIF('96组'!$X$2:$X$49,"A") | E9: =COUNTIF('96组'!$X$2:$X$49,"C") | F9: =COUNTIF('96组'!$X$2:$X$49,"G") | G9: =COUNTIF('96组'!$X$2:$X$49,"T") | H9: =(E9+F9)/48 | I9: =(D9+E9)/48 | J9: =(D9+G9)/48 | K9: =IF(AND(H9>=0.4,H9<=0.6,I9>=0.4,I9<=0.6,J9>=0.4,J9<=0.6,MIN(D9:G9)>=7.2),"是","否")
A10: 48 组 | B10: i5 | C10: 9 | D10: =COUNTIF('96组'!$Y$2:$Y$49,"A") | E10: =COUNTIF('96组'!$Y$2:$Y$49,"C") | F10: =COUNTIF('96组'!$Y$2:$Y$49,"G") | G10: =COUNTIF('96组'!$Y$2:$Y$49,"T") | H10: =(E10+F10)/48 | I10: =(D10+E10)/48 | J10: =(D10+G10)/48 | K10: =IF(AND(H10>=0.4,H10<=0.6,I10>=0.4,I10<=0.6,J10>=0.4,J10<=0.6,MIN(D10:G10)>=7.2),"是","否")
A11: 48 组 | B11: i5 | C11: 10 | D11: =COUNTIF('96组'!$Z$2:$Z$49,"A") | E11: =COUNTIF('96组'!$Z$2:$Z$49,"C") | F11: =COUNTIF('96组'!$Z$2:$Z$49,"G") | G11: =COUNTIF('96组'!$Z$2:$Z$49,"T") | H11: =(E11+F11)/48 | I11: =(D11+E11)/48 | J11: =(D11+G11)/48 | K11: =IF(AND(H11>=0.4,H11<=0.6,I11>=0.4,I11<=0.6,J11>=0.4,J11<=0.6,MIN(D11:G11)>=7.2),"是","否")
A12: 48 组 | B12: i7 | C12: 1 | D12: =COUNTIF('96组'!$AA$2:$AA$49,"A") | E12: =COUNTIF('96组'!$AA$2:$AA$49,"C") | F12: =COUNTIF('96组'!$AA$2:$AA$49,"G") | G12: =COUNTIF('96组'!$AA$2:$AA$49,"T") | H12: =(E12+F12)/48 | I12: =(D12+E12)/48 | J12: =(D12+G12)/48 | K12: =IF(AND(H12>=0.4,H12<=0.6,I12>=0.4,I12<=0.6,J12>=0.4,J12<=0.6,MIN(D12:G12)>=7.2),"是","否")
A13: 48 组 | B13: i7 | C13: 2 | D13: =COUNTIF('96组'!$AB$2:$AB$49,"A") | E13: =COUNTIF('96组'!$AB$2:$AB$49,"C") | F13: =COUNTIF('96组'!$AB$2:$AB$49,"G") | G13: =COUNTIF('96组'!$AB$2:$AB$49,"T") | H13: =(E13+F13)/48 | I13: =(D13+E13)/48 | J13: =(D13+G13)/48 | K13: =IF(AND(H13>=0.4,H13<=0.6,I13>=0.4,I13<=0.6,J13>=0.4,J13<=0.6,MIN(D13:G13)>=7.2),"是","否")
A14: 48 组 | B14: i7 | C14: 3 | D14: =COUNTIF('96组'!$AC$2:$AC$49,"A") | E14: =COUNTIF('96组'!$AC$2:$AC$49,"C") | F14: =COUNTIF('96组'!$AC$2:$AC$49,"G") | G14: =COUNTIF('96组'!$AC$2:$AC$49,"T") | H14: =(E14+F14)/48 | I14: =(D14+E14)/48 | J14: =(D14+G14)/48 | K14: =IF(AND(H14>=0.4,H14<=0.6,I14>=0.4,I14<=0.6,J14>=0.4,J14<=0.6,MIN(D14:G14)>=7.2),"是","否")
A15: 48 组 | B15: i7 | C15: 4 | D15: =COUNTIF('96组'!$AD$2:$AD$49,"A") | E15: =COUNTIF('96组'!$AD$2:$AD$49,"C") | F15: =COUNTIF('96组'!$AD$2:$AD$49,"G") | G15: =COUNTIF('96组'!$AD$2:$AD$49,"T") | H15: =(E15+F15)/48 | I15: =(D15+E15)/48 | J15: =(D15+G15)/48 | K15: =IF(AND(H15>=0.4,H15<=0.6,I15>=0.4,I15<=0.6,J15>=0.4,J15<=0.6,MIN(D15:G15)>=7.2),"是","否")
A16: 48 组 | B16: i7 | C16: 5 | D16: =COUNTIF('96组'!$AE$2:$AE$49,"A") | E16: =COUNTIF('96组'!$AE$2:$AE$49,"C") | F16: =COUNTIF('96组'!$AE$2:$AE$49,"G") | G16: =COUNTIF('96组'!$AE$2:$AE$49,"T") | H16: =(E16+F16)/48 | I16: =(D16+E16)/48 | J16: =(D16+G16)/48 | K16: =IF(AND(H16>=0.4,H16<=0.6,I16>=0.4,I16<=0.6,J16>=0.4,J16<=0.6,MIN(D16:G16)>=7.2),"是","否")
A17: 48 组 | B17: i7 | C17: 6 | D17: =COUNTIF('96组'!$AF$2:$AF$49,"A") | E17: =COUNTIF('96组'!$AF$2:$AF$49,"C") | F17: =COUNTIF('96组'!$AF$2:$AF$49,"G") | G17: =COUNTIF('96组'!$AF$2:$AF$49,"T") | H17: =(E17+F17)/48 | I17: =(D17+E17)/48 | J17: =(D17+G17)/48 | K17: =IF(AND(H17>=0.4,H17<=0.6,I17>=0.4,I17<=0.6,J17>=0.4,J17<=0.6,MIN(D17:G17)>=7.2),"是","否")
A18: 48 组 | B18: i7 | C18: 7 | D18: =COUNTIF('96组'!$AG$2:$AG$49,"A") | E18: =COUNTIF('96组'!$AG$2:$AG$49,"C") | F18: =COUNTIF('96组'!$AG$2:$AG$49,"G") | G18: =COUNTIF('96组'!$AG$2:$AG$49,"T") | H18: =(E18+F18)/48 | I18: =(D18+E18)/48 | J18: =(D18+G18)/48 | K18: =IF(AND(H18>=0.4,H18<=0.6,I18>=0.4,I18<=0.6,J18>=0.4,J18<=0.6,MIN(D18:G18)>=7.2),"是","否")
A19: 48 组 | B19: i7 | C19: 8 | D19: =COUNTIF('96组'!$AH$2:$AH$49,"A") | E19: =COUNTIF('96组'!$AH$2:$AH$49,"C") | F19: =COUNTIF('96组'!$AH$2:$AH$49,"G") | G19: =COUNTIF('96组'!$AH$2:$AH$49,"T") | H19: =(E19+F19)/48 | I19: =(D19+E19)/48 | J19: =(D19+G19)/48 | K19: =IF(AND(H19>=0.4,H19<=0.6,I19>=0.4,I19<=0.6,J19>=0.4,J19<=0.6,MIN(D19:G19)>=7.2),"是","否")
A20: 48 组 | B20: i7 | C20: 9 | D20: =COUNTIF('96组'!$AI$2:$AI$49,"A") | E20: =COUNTIF('96组'!$AI$2:$AI$49,"C") | F20: =COUNTIF('96组'!$AI$2:$AI$49,"G") | G20: =COUNTIF('96组'!$AI$2:$AI$49,"T") | H20: =(E20+F20)/48 | I20: =(D20+E20)/48 | J20: =(D20+G20)/48 | K20: =IF(AND(H20>=0.4,H20<=0.6,I20>=0.4,I20<=0.6,J20>=0.4,J20<=0.6,MIN(D20:G20)>=7.2),"是","否")
A21: 48 组 | B21: i7 | C21: 10 | D21: =COUNTIF('96组'!$AJ$2:$AJ$49,"A") | E21: =COUNTIF('96组'!$AJ$2:$AJ$49,"C") | F21: =COUNTIF('96组'!$AJ$2:$AJ$49,"G") | G21: =COUNTIF('96组'!$AJ$2:$AJ$49,"T") | H21: =(E21+F21)/48 | I21: =(D21+E21)/48 | J21: =(D21+G21)/48 | K21: =IF(AND(H21>=0.4,H21<=0.6,I21>=0.4,I21<=0.6,J21>=0.4,J21<=0.6,MIN(D21:G21)>=7.2),"是","否")
A22: 96 组 | B22: i5 | C22: 1 | D22: =COUNTIF('96组'!$Q$2:$Q$97,"A") | E22: =COUNTIF('96组'!$Q$2:$Q$97,"C") | F22: =COUNTIF('96组'!$Q$2:$Q$97,"G") | G22: =COUNTIF('96组'!$Q$2:$Q$97,"T") | H22: =(E22+F22)/96 | I22: =(D22+E22)/96 | J22: =(D22+G22)/96 | K22: =IF(AND(H22>=0.4,H22<=0.6,I22>=0.4,I22<=0.6,J22>=0.4,J22<=0.6,MIN(D22:G22)>=14.4),"是","否")
A23: 96 组 | B23: i5 | C23: 2 | D23: =COUNTIF('96组'!$R$2:$R$97,"A") | E23: =COUNTIF('96组'!$R$2:$R$97,"C") | F23: =COUNTIF('96组'!$R$2:$R$97,"G") | G23: =COUNTIF('96组'!$R$2:$R$97,"T") | H23: =(E23+F23)/96 | I23: =(D23+E23)/96 | J23: =(D23+G23)/96 | K23: =IF(AND(H23>=0.4,H23<=0.6,I23>=0.4,I23<=0.6,J23>=0.4,J23<=0.6,MIN(D23:G23)>=14.4),"是","否")
A24: 96 组 | B24: i5 | C24: 3 | D24: =COUNTIF('96组'!$S$2:$S$97,"A") | E24: =COUNTIF('96组'!$S$2:$S$97,"C") | F24: =COUNTIF('96组'!$S$2:$S$97,"G") | G24: =COUNTIF('96组'!$S$2:$S$97,"T") | H24: =(E24+F24)/96 | I24: =(D24+E24)/96 | J24: =(D24+G24)/96 | K24: =IF(AND(H24>=0.4,H24<=0.6,I24>=0.4,I24<=0.6,J24>=0.4,J24<=0.6,MIN(D24:G24)>=14.4),"是","否")
A25: 96 组 | B25: i5 | C25: 4 | D25: =COUNTIF('96组'!$T$2:$T$97,"A") | E25: =COUNTIF('96组'!$T$2:$T$97,"C") | F25: =COUNTIF('96组'!$T$2:$T$97,"G") | G25: =COUNTIF('96组'!$T$2:$T$97,"T") | H25: =(E25+F25)/96 | I25: =(D25+E25)/96 | J25: =(D25+G25)/96 | K25: =IF(AND(H25>=0.4,H25<=0.6,I25>=0.4,I25<=0.6,J25>=0.4,J25<=0.6,MIN(D25:G25)>=14.4),"是","否")
A26: 96 组 | B26: i5 | C26: 5 | D26: =COUNTIF('96组'!$U$2:$U$97,"A") | E26: =COUNTIF('96组'!$U$2:$U$97,"C") | F26: =COUNTIF('96组'!$U$2:$U$97,"G") | G26: =COUNTIF('96组'!$U$2:$U$97,"T") | H26: =(E26+F26)/96 | I26: =(D26+E26)/96 | J26: =(D26+G26)/96 | K26: =IF(AND(H26>=0.4,H26<=0.6,I26>=0.4,I26<=0.6,J26>=0.4,J26<=0.6,MIN(D26:G26)>=14.4),"是","否")
A27: 96 组 | B27: i5 | C27: 6 | D27: =COUNTIF('96组'!$V$2:$V$97,"A") | E27: =COUNTIF('96组'!$V$2:$V$97,"C") | F27: =COUNTIF('96组'!$V$2:$V$97,"G") | G27: =COUNTIF('96组'!$V$2:$V$97,"T") | H27: =(E27+F27)/96 | I27: =(D27+E27)/96 | J27: =(D27+G27)/96 | K27: =IF(AND(H27>=0.4,H27<=0.6,I27>=0.4,I27<=0.6,J27>=0.4,J27<=0.6,MIN(D27:G27)>=14.4),"是","否")
A28: 96 组 | B28: i5 | C28: 7 | D28: =COUNTIF('96组'!$W$2:$W$97,"A") | E28: =COUNTIF('96组'!$W$2:$W$97,"C") | F28: =COUNTIF('96组'!$W$2:$W$97,"G") | G28: =COUNTIF('96组'!$W$2:$W$97,"T") | H28: =(E28+F28)/96 | I28: =(D28+E28)/96 | J28: =(D28+G28)/96 | K28: =IF(AND(H28>=0.4,H28<=0.6,I28>=0.4,I28<=0.6,J28>=0.4,J28<=0.6,MIN(D28:G28)>=14.4),"是","否")
A29: 96 组 | B29: i5 | C29: 8 | D29: =COUNTIF('96组'!$X$2:$X$97,"A") | E29: =COUNTIF('96组'!$X$2:$X$97,"C") | F29: =COUNTIF('96组'!$X$2:$X$97,"G") | G29: =COUNTIF('96组'!$X$2:$X$97,"T") | H29: =(E29+F29)/96 | I29: =(D29+E29)/96 | J29: =(D29+G29)/96 | K29: =IF(AND(H29>=0.4,H29<=0.6,I29>=0.4,I29<=0.6,J29>=0.4,J29<=0.6,MIN(D29:G29)>=14.4),"是","否")
A30: 96 组 | B30: i5 | C30: 9 | D30: =COUNTIF('96组'!$Y$2:$Y$97,"A") | E30: =COUNTIF('96组'!$Y$2:$Y$97,"C") | F30: =COUNTIF('96组'!$Y$2:$Y$97,"G") | G30: =COUNTIF('96组'!$Y$2:$Y$97,"T") | H30: =(E30+F30)/96 | I30: =(D30+E30)/96 | J30: =(D30+G30)/96 | K30: =IF(AND(H30>=0.4,H30<=0.6,I30>=0.4,I30<=0.6,J30>=0.4,J30<=0.6,MIN(D30:G30)>=14.4),"是","否")
A31: 96 组 | B31: i5 | C31: 10 | D31: =COUNTIF('96组'!$Z$2:$Z$97,"A") | E31: =COUNTIF('96组'!$Z$2:$Z$97,"C") | F31: =COUNTIF('96组'!$Z$2:$Z$97,"G") | G31: =COUNTIF('96组'!$Z$2:$Z$97,"T") | H31: =(E31+F31)/96 | I31: =(D31+E31)/96 | J31: =(D31+G31)/96 | K31: =IF(AND(H31>=0.4,H31<=0.6,I31>=0.4,I31<=0.6,J31>=0.4,J31<=0.6,MIN(D31:G31)>=14.4),"是","否")
A32: 96 组 | B32: i7 | C32: 1 | D32: =COUNTIF('96组'!$AA$2:$AA$97,"A") | E32: =COUNTIF('96组'!$AA$2:$AA$97,"C") | F32: =COUNTIF('96组'!$AA$2:$AA$97,"G") | G32: =COUNTIF('96组'!$AA$2:$AA$97,"T") | H32: =(E32+F32)/96 | I32: =(D32+E32)/96 | J32: =(D32+G32)/96 | K32: =IF(AND(H32>=0.4,H32<=0.6,I32>=0.4,I32<=0.6,J32>=0.4,J32<=0.6,MIN(D32:G32)>=14.4),"是","否")
A33: 96 组 | B33: i7 | C33: 2 | D33: =COUNTIF('96组'!$AB$2:$AB$97,"A") | E33: =COUNTIF('96组'!$AB$2:$AB$97,"C") | F33: =COUNTIF('96组'!$AB$2:$AB$97,"G") | G33: =COUNTIF('96组'!$AB$2:$AB$97,"T") | H33: =(E33+F33)/96 | I33: =(D33+E33)/96 | J33: =(D33+G33)/96 | K33: =IF(AND(H33>=0.4,H33<=0.6,I33>=0.4,I33<=0.6,J33>=0.4,J33<=0.6,MIN(D33:G33)>=14.4),"是","否")
A34: 96 组 | B34: i7 | C34: 3 | D34: =COUNTIF('96组'!$AC$2:$AC$97,"A") | E34: =COUNTIF('96组'!$AC$2:$AC$97,"C") | F34: =COUNTIF('96组'!$AC$2:$AC$97,"G") | G34: =COUNTIF('96组'!$AC$2:$AC$97,"T") | H34: =(E34+F34)/96 | I34: =(D34+E34)/96 | J34: =(D34+G34)/96 | K34: =IF(AND(H34>=0.4,H34<=0.6,I34>=0.4,I34<=0.6,J34>=0.4,J34<=0.6,MIN(D34:G34)>=14.4),"是","否")
A35: 96 组 | B35: i7 | C35: 4 | D35: =COUNTIF('96组'!$AD$2:$AD$97,"A") | E35: =COUNTIF('96组'!$AD$2:$AD$97,"C") | F35: =COUNTIF('96组'!$AD$2:$AD$97,"G") | G35: =COUNTIF('96组'!$AD$2:$AD$97,"T") | H35: =(E35+F35)/96 | I35: =(D35+E35)/96 | J35: =(D35+G35)/96 | K35: =IF(AND(H35>=0.4,H35<=0.6,I35>=0.4,I35<=0.6,J35>=0.4,J35<=0.6,MIN(D35:G35)>=14.4),"是","否")
A36: 96 组 | B36: i7 | C36: 5 | D36: =COUNTIF('96组'!$AE$2:$AE$97,"A") | E36: =COUNTIF('96组'!$AE$2:$AE$97,"C") | F36: =COUNTIF('96组'!$AE$2:$AE$97,"G") | G36: =COUNTIF('96组'!$AE$2:$AE$97,"T") | H36: =(E36+F36)/96 | I36: =(D36+E36)/96 | J36: =(D36+G36)/96 | K36: =IF(AND(H36>=0.4,H36<=0.6,I36>=0.4,I36<=0.6,J36>=0.4,J36<=0.6,MIN(D36:G36)>=14.4),"是","否")
A37: 96 组 | B37: i7 | C37: 6 | D37: =COUNTIF('96组'!$AF$2:$AF$97,"A") | E37: =COUNTIF('96组'!$AF$2:$AF$97,"C") | F37: =COUNTIF('96组'!$AF$2:$AF$97,"G") | G37: =COUNTIF('96组'!$AF$2:$AF$97,"T") | H37: =(E37+F37)/96 | I37: =(D37+E37)/96 | J37: =(D37+G37)/96 | K37: =IF(AND(H37>=0.4,H37<=0.6,I37>=0.4,I37<=0.6,J37>=0.4,J37<=0.6,MIN(D37:G37)>=14.4),"是","否")
A38: 96 组 | B38: i7 | C38: 7 | D38: =COUNTIF('96组'!$AG$2:$AG$97,"A") | E38: =COUNTIF('96组'!$AG$2:$AG$97,"C") | F38: =COUNTIF('96组'!$AG$2:$AG$97,"G") | G38: =COUNTIF('96组'!$AG$2:$AG$97,"T") | H38: =(E38+F38)/96 | I38: =(D38+E38)/96 | J38: =(D38+G38)/96 | K38: =IF(AND(H38>=0.4,H38<=0.6,I38>=0.4,I38<=0.6,J38>=0.4,J38<=0.6,MIN(D38:G38)>=14.4),"是","否")
A39: 96 组 | B39: i7 | C39: 8 | D39: =COUNTIF('96组'!$AH$2:$AH$97,"A") | E39: =COUNTIF('96组'!$AH$2:$AH$97,"C") | F39: =COUNTIF('96组'!$AH$2:$AH$97,"G") | G39: =COUNTIF('96组'!$AH$2:$AH$97,"T") | H39: =(E39+F39)/96 | I39: =(D39+E39)/96 | J39: =(D39+G39)/96 | K39: =IF(AND(H39>=0.4,H39<=0.6,I39>=0.4,I39<=0.6,J39>=0.4,J39<=0.6,MIN(D39:G39)>=14.4),"是","否")
A40: 96 组 | B40: i7 | C40: 9 | D40: =COUNTIF('96组'!$AI$2:$AI$97,"A") | E40: =COUNTIF('96组'!$AI$2:$AI$97,"C") | F40: =COUNTIF('96组'!$AI$2:$AI$97,"G") | G40: =COUNTIF('96组'!$AI$2:$AI$97,"T") | H40: =(E40+F40)/96 | I40: =(D40+E40)/96 | J40: =(D40+G40)/96 | K40: =IF(AND(H40>=0.4,H40<=0.6,I40>=0.4,I40<=0.6,J40>=0.4,J40<=0.6,MIN(D40:G40)>=14.4),"是","否")
...
